Workbook

Sheet Spatial
A1: Floor | B1: Room | C1: Zone | D1: Row | E1: Rack | F1: Pod | G1: Server | H1: Networking Device | I1: Storage Device
A2: FLOOR-1 | B2: ROOM-1-3 | C2: ZONE-R3-Z1W | D2: ROW-R3-Z1W-R1 | E2: RACK-R3-Z1W-R1-01 | F2: POD-05
A3: FLOOR-1 | B3: ROOM-1-3 | C3: ZONE-R3-Z1W | D3: ROW-R3-Z1W-R1 | E3: RACK-R3-Z1W-R1-02 | F3: POD-05
A4: FLOOR-1 | B4: ROOM-1-3 | C4: ZONE-R3-Z1W | D4: ROW-R3-Z1W-R1 | E4: RACK-R3-Z1W-R1-03 | F4: POD-05
A5: FLOOR-1 | B5: ROOM-1-3 | C5: ZONE-R3-Z1W | D5: ROW-R3-Z1W-R1 | E5: RACK-R3-Z1W-R1-04 | F5: POD-05
A6: FLOOR-1 | B6: ROOM-1-3 | C6: ZONE-R3-Z1W | D6: ROW-R3-Z1W-R1 | E6: RACK-R3-Z1W-R1-05 | F6: POD-05
A7: FLOOR-1 | B7: ROOM-1-3 | C7: ZONE-R3-Z1W | D7: ROW-R3-Z1W-R1 | E7: RACK-R3-Z1W-R1-06 | F7: POD-05
A8: FLOOR-1 | B8: ROOM-1-3 | C8: ZONE-R3-Z1W | D8: ROW-R3-Z1W-R1 | E8: RACK-R3-Z1W-R1-07 | F8: POD-05
A9: FLOOR-1 | B9: ROOM-1-3 | C9: ZONE-R3-Z1W | D9: ROW-R3-Z1W-R1 | E9: RACK-R3-Z1W-R1-08 | F9: POD-05
A10: FLOOR-1 | B10: ROOM-1-3 | C10: ZONE-R3-Z1W | D10: ROW-R3-Z1W-R1 | E10: RACK-R3-Z1W-R1-09 | F10: POD-05
A11: FLOOR-1 | B11: ROOM-1-3 | C11: ZONE-R3-Z1W | D11: ROW-R3-Z1W-R1 | E11: RACK-R3-Z1W-R1-10 | F11: POD-05
A12: FLOOR-1 | B12: ROOM-1-3 | C12: ZONE-R3-Z1W | D12: ROW-R3-Z1W-R1 | E12: RACK-R3-Z1W-R1-11 | F12: POD-05
A13: FLOOR-1 | B13: ROOM-1-3 | C13: ZONE-R3-Z1W | D13: ROW-R3-Z1W-R1 | E13: RACK-R3-Z1W-R1-12 | F13: POD-05
... A217: FLOOR-1 | B217: ROOM-1-5 | C217: ZONE-R5-Z2E | D217: ROW-R5-Z2E-R2 | E217: RACK-R5-Z2E-R2-12 | F217: POD-09

Sheet Zone-Aisle
A1: Zone | B1: Aisle
A2: ZONE-R3-Z1W | B2: AISLE-R3-Z1W-R1H
A3: ZONE-R3-Z1W | B3: AISLE-R3-Z1W-R1R2C
A4: ZONE-R3-Z2W | B4: AISLE-R3-Z2W-R1H
A5: ZONE-R3-Z2W | B5: AISLE-R3-Z2W-R1R2C
A6: ZONE-R3-Z3W | B6: AISLE-R3-Z3W-R1H
A7: ZONE-R3-Z3W | B7: AISLE-R3-Z3W-R1R2C
A8: ZONE-R3-Z3W | B8: AISLE-R3-Z3W-R2H
A9: ZONE-R3-Z4E | B9: AISLE-R3-Z4E-R1H
A10: ZONE-R3-Z4E | B10: AISLE-R3-Z4E-R1R2C
A11: ZONE-R3-Z5E | B11: AISLE-R3-Z5E-R1H
A12: ZONE-R3-Z5E | B12: AISLE-R3-Z5E-R1R2C
... A24: ZONE-R5-Z2E | B24: AISLE-R5-Z2E-R2H

Sheet Sheet2
A3: Count of Rack
A4: Capacity Cell | B4: Total
A5: CC-R1R2 | B5: 48
A6: CC-R3 | B6: 144
A7: CC-R4 | B7: 24
A8: CC-R5E | B8: 24
A9: CC-R5W | B9: 24
A10: (blank)
A11: Grand Total | B11: 264

Sheet Master_Rack
A1: Zone | B1: Row | C1: Planned Rack Density (kW) | D1: Cold Aisle | E1: Hot Aisle | F1: Liquid Loop | G1: Air Zone | H1: Rack | I1: Pod | J1: Rack PDU (A Feed) | K1: Rack PDU (B Feed) | L1: Rack_Circuit_Capacity_(design) | M1: Rack_Max_Liquid_Load | N1: Rack_Max_Air_Load | O1: Rack_Circuit_Capacity_(rated) | P1: Rack_LiquidCool_Fraction | Q1: Rack_AirCool_Fraction | R1: RPP (A Feed) | S1: RPP (B Feed) | T1: Room PDU (A Feed) | U1: Room PDU (B Feed) | V1: UPS (A Feed) | W1: UPS (B Feed) | X1: BESS | Y1: Switch Gear (A Feed) | Z1: Switch Gear (B Feed) | AA1: Utility (A Feed) | AB1: Utility (B Feed) | AC1: Generator (A Feed) | AD1: Generator (B Feed) | AE1: Capacity Cell | AF1: Room Bundle | AG1: Room PDU Bundle | AH1: UPS Bundle | AI1: ITL-SJ-Meridian-C01-PP01 | AJ1: LCL-SJ-Meridian-C01-PP01 | AK1: ACL-SJ-Meridian-C01-PP01 | AL1: ITL-SJ-Pacific-C01-PD01 | AM1: LCL-SJ-Pacific-C01-PD01 | AN1: ACL-SJ-Pacific-C01-PD01 | AO1: ITL-SJ-Pacific-C01-PD02 | AP1: ACL-SJ-Pacific-C01-PD02 | AQ1: LCL-SJ-Pacific-C01-PD02 | AR1: ITL-SJ-Pacific-C01-PD03 | AS1: ACL-SJ-Pacific-C01-PD03 | AT1: LCL-SJ-Pacific-C01-PD03 | AU1: ITL-SJ-Pacific-C01-PD04 | AV1: ACL-SJ-Pacific-C01-PD04 | AW1: LCL-SJ-Pacific-C01-PD04 | AX1: ITL-SJ-Keystone-C01-PP01 | AY1: ACL-SJ-Keystone-C01-PP01 | AZ1: LCL-SJ-Keystone-C01-PP01 | BA1: LCM-SJ-Meridian-C01-PP01 | BB1: LCM-SJ-Pacific-C01-PD01 | BC1: LCM-SJ-Pacific-C01-PD02 | BD1: LCM-SJ-Pacific-C01-PD03 | BE1: LCM-SJ-Pacific-C01-PD04 | BF1: LCM-SJ-Keystone-C01-PP01 | BG1: LCM-SJ-Meridian-C01-PP01% | BH1: LCM-SJ-Pacific-C01-PD01% | BI1: LCM-SJ-Pacific-C01-PD02% | BJ1: LCM-SJ-Pacific-C01-PD03% | BK1: LCM-SJ-Pacific-C01-PD04% | BL1: LCM-SJ-Keystone-C01-PP01% | BM1: RDHx | BN1: RDHx_MaxHeat_Removal | BO1: DTC | BP1: DTC_MaxCool_Capacity | BQ1: COUNT-SJ-Meridian-C01-PP01 | BR1: COUNT-SJ-Pacific-C01-PD01 | BS1: COUNT-SJ-Pacific-C01-PD02 | BT1: COUNT-SJ-Pacific-C01-PD03 | BU1: COUNT-SJ-Pacific-C01-PD04 | BV1: COUNT-SJ-Keystone-C01-PP01
A2: ZONE-R3-Z1W | B2: ROW-R3-Z1W-R1 | C2: 30 | F2: LL-R3-W | G2: AIRZONE-R3-W1 | H2: RACK-R3-Z1W-R1-01 | I2: POD-05 | J2: ="RACKPDU-"&H2&"-A" -> RACKPDU-RACK-R3-Z1W-R1-01-A | K2: ="RACKPDU-"&H2&"-B" -> RACKPDU-RACK-R3-Z1W-R1-01-B | L2: 30 | M2: =VLOOKUP($H2,'Cooling-Rack'!$A$2:$G$265,5,FALSE) -> 22.5 | N2: =VLOOKUP($H2,'Cooling-Rack'!$A$2:$G$265,7,FALSE) -> 7.5 | O2: 36 | P2: 0.75 | Q2: 0.25 | R2: RPP-R3-A1 | S2: RPP-R3-B1 | T2: RPDU-R3-A | U2: RPDU-R3R4-B | V2: UPS-02-A | W2: UPS-02-B | X2: BESS-01 | Y2: SWGR-01 | Z2: SWGR-02 | AA2: UTIL-01 | AB2: UTIL-02 | AC2: GEN-01 | AD2: GEN-02 | AE2: CC-R3 | AF2: BDL-R3 | AG2: BDL-RPDU-R3R4 | AH2: BDL-UPS-02 | AL2: 30 | AM2: =AL2/$L2*$M2 -> 22.5 | AN2: =AL2/$L2*$N2 -> 7.5 | AO2: 30 | AP2: =AO2/$L2*$M2 -> 22.5 | AQ2: =AO2/$L2*$N2 -> 7.5 | BA2: =$L2-$AI2 -> 30 | BB2: =$L2-$AL2 -> 0 | BC2: =$L2-$AO2 -> 0 | BD2: =$L2-$AR2 -> 30 | BE2: =$L2-$AU2 -> 30 | BF2: =$L2-$AX2 -> 30 | BG2: =BA2/$L2 -> 1 | BH2: =BB2/$L2 -> 0 | BI2: =BC2/$L2 -> 0 | BJ2: =BD2/$L2 -> 1 | BK2: =BE2/$L2 -> 1 | BL2: =BF2/$L2 -> 1 | BO2: DTC-RACK-R3-Z1W-R1-01 | BP2: =M2/0.9 -> 25 | BQ2: =IF($AI2>0, 1, 0) -> 0 | BR2: =IF($AL2>0, 1, 0) -> 1 | BS2: =IF($AO2>0, 1, 0) -> 1 | BT2: =IF($AR2>0, 1, 0) -> 0 | BU2: =IF($AU2>0, 1, 0) -> 0 | BV2: =IF(AX2>0, 1, 0) -> 0
A3: ZONE-R3-Z1W | B3: ROW-R3-Z1W-R1 | C3: 30 | F3: LL-R3-W | G3: AIRZONE-R3-W1 | H3: RACK-R3-Z1W-R1-02 | I3: POD-05 | J3: ="RACKPDU-"&H3&"-A" -> RACKPDU-RACK-R3-Z1W-R1-02-A | K3: ="RACKPDU-"&H3&"-B" -> RACKPDU-RACK-R3-Z1W-R1-02-B | L3: 30 | M3: =VLOOKUP($H3,'Cooling-Rack'!$A$2:$G$265,5,FALSE) -> 22.5 | N3: =VLOOKUP($H3,'Cooling-Rack'!$A$2:$G$265,7,FALSE) -> 7.5 | O3: 36 | P3: 0.75 | Q3: 0.25 | R3: RPP-R3-A1 | S3: RPP-R3-B1 | T3: RPDU-R3-A | U3: RPDU-R3R4-B | V3: UPS-02-A | W3: UPS-02-B | X3: BESS-01 | Y3: SWGR-01 | Z3: SWGR-02 | AA3: UTIL-01 | AB3: UTIL-02 | AC3: GEN-01 | AD3: GEN-02 | AE3: CC-R3 | AF3: BDL-R3 | AG3: BDL-RPDU-R3R4 | AH3: BDL-UPS-02 | AL3: 30 | AM3: =AL3/$L3*$M3 -> 22.5 | AN3: =AL3/$L3*$N3 -> 7.5 | AO3: 30 | AP3: =AO3/$L3*$M3 -> 22.5 | AQ3: =AO3/$L3*$N3 -> 7.5 | BA3: =$L3-$AI3 -> 30 | BB3: =$L3-$AL3 -> 0 | BC3: =$L3-$AO3 -> 0 | BD3: =$L3-$AR3 -> 30 | BE3: =$L3-$AU3 -> 30 | BF3: =$L3-$AX3 -> 30 | BG3: =BA3/$L3 -> 1 | BH3: =BB3/$L3 -> 0 | BI3: =BC3/$L3 -> 0 | BJ3: =BD3/$L3 -> 1 | BK3: =BE3/$L3 -> 1 | BL3: =BF3/$L3 -> 1 | BO3: DTC-RACK-R3-Z1W-R1-02 | BP3: =M3/0.9 -> 25 | BQ3: =IF($AI3>0, 1, 0) -> 0 | BR3: =IF($AL3>0, 1, 0) -> 1 | BS3: =IF($AO3>0, 1, 0) -> 1 | BT3: =IF($AR3>0, 1, 0) -> 0 | BU3: =IF($AU3>0, 1, 0) -> 0 | BV3: =IF(AX3>0, 1, 0) -> 0
A4: ZONE-R3-Z1W | B4: ROW-R3-Z1W-R1 | C4: 30 | F4: LL-R3-W | G4: AIRZONE-R3-W1 | H4: RACK-R3-Z1W-R1-03 | I4: POD-05 | J4: ="RACKPDU-"&H4&"-A" -> RACKPDU-RACK-R3-Z1W-R1-03-A | K4: ="RACKPDU-"&H4&"-B" -> RACKPDU-RACK-R3-Z1W-R1-03-B | L4: 30 | M4: =VLOOKUP($H4,'Cooling-Rack'!$A$2:$G$265,5,FALSE) -> 22.5 | N4: =VLOOKUP($H4,'Cooling-Rack'!$A$2:$G$265,7,FALSE) -> 7.5 | O4: 36 | P4: 0.75 | Q4: 0.25 | R4: RPP-R3-A1 | S4: RPP-R3-B1 | T4: RPDU-R3-A | U4: RPDU-R3R4-B | V4: UPS-02-A | W4: UPS-02-B | X4: BESS-01 | Y4: SWGR-01 | Z4: SWGR-02 | AA4: UTIL-01 | AB4: UTIL-02 | AC4: GEN-01 | AD4: GEN-02 | AE4: CC-R3 | AF4: BDL-R3 | AG4: BDL-RPDU-R3R4 | AH4: BDL-UPS-02 | AL4: 30 | AM4: =AL4/$L4*$M4 -> 22.5 | AN4: =AL4/$L4*$N4 -> 7.5 | AO4: 30 | AP4: =AO4/$L4*$M4 -> 22.5 | AQ4: =AO4/$L4*$N4 -> 7.5 | BA4: =$L4-$AI4 -> 30 | BB4: =$L4-$AL4 -> 0 | BC4: =$L4-$AO4 -> 0 | BD4: =$L4-$AR4 -> 30 | BE4: =$L4-$AU4 -> 30 | BF4: =$L4-$AX4 -> 30 | BG4: =BA4/$L4 -> 1 | BH4: =BB4/$L4 -> 0 | BI4: =BC4/$L4 -> 0 | BJ4: =BD4/$L4 -> 1 | BK4: =BE4/$L4 -> 1 | BL4: =BF4/$L4 -> 1 | BO4: DTC-RACK-R3-Z1W-R1-03 | BP4: =M4/0.9 -> 25 | BQ4: =IF($AI4>0, 1, 0) -> 0 | BR4: =IF($AL4>0, 1, 0) -> 1 | BS4: =IF($AO4>0, 1, 0) -> 1 | BT4: =IF($AR4>0, 1, 0) -> 0 | BU4: =IF($AU4>0, 1, 0) -> 0 | BV4: =IF(AX4>0, 1, 0) -> 0
A5: ZONE-R3-Z1W | B5: ROW-R3-Z1W-R1 | C5: 30 | F5: LL-R3-W | G5: AIRZONE-R3-W1 | H5: RACK-R3-Z1W-R1-04 | I5: POD-05 | J5: ="RACKPDU-"&H5&"-A" -> RACKPDU-RACK-R3-Z1W-R1-04-A | K5: ="RACKPDU-"&H5&"-B" -> RACKPDU-RACK-R3-Z1W-R1-04-B | L5: 30 | M5: =VLOOKUP($H5,'Cooling-Rack'!$A$2:$G$265,5,FALSE) -> 22.5 | N5: =VLOOKUP($H5,'Cooling-Rack'!$A$2:$G$265,7,FALSE) -> 7.5 | O5: 36 | P5: 0.75 | Q5: 0.25 | R5: RPP-R3-A1 | S5: RPP-R3-B1 | T5: RPDU-R3-A | U5: RPDU-R3R4-B | V5: UPS-02-A | W5: UPS-02-B | X5: BESS-01 | Y5: SWGR-01 | Z5: SWGR-02 | AA5: UTIL-01 | AB5: UTIL-02 | AC5: GEN-01 | AD5: GEN-02 | AE5: CC-R3 | AF5: BDL-R3 | AG5: BDL-RPDU-R3R4 | AH5: BDL-UPS-02 | AL5: 30 | AM5: =AL5/$L5*$M5 -> 22.5 | AN5: =AL5/$L5*$N5 -> 7.5 | AO5: 30 | AP5: =AO5/$L5*$M5 -> 22.5 | AQ5: =AO5/$L5*$N5 -> 7.5 | BA5: =$L5-$AI5 -> 30 | BB5: =$L5-$AL5 -> 0 | BC5: =$L5-$AO5 -> 0 | BD5: =$L5-$AR5 -> 30 | BE5: =$L5-$AU5 -> 30 | BF5: =$L5-$AX5 -> 30 | BG5: =BA5/$L5 -> 1 | BH5: =BB5/$L5 -> 0 | BI5: =BC5/$L5 -> 0 | BJ5: =BD5/$L5 -> 1 | BK5: =BE5/$L5 -> 1 | BL5: =BF5/$L5 -> 1 | BO5: DTC-RACK-R3-Z1W-R1-04 | BP5: =M5/0.9 -> 25 | BQ5: =IF($AI5>0, 1, 0) -> 0 | BR5: =IF($AL5>0, 1, 0) -> 1 | BS5: =IF($AO5>0, 1, 0) -> 1 | BT5: =IF($AR5>0, 1, 0) -> 0 | BU5: =IF($AU5>0, 1, 0) -> 0 | BV5: =IF(AX5>0, 1, 0) -> 0
A6: ZONE-R3-Z1W | B6: ROW-R3-Z1W-R1 | C6: 30 | F6: LL-R3-W | G6: AIRZONE-R3-W1 | H6: RACK-R3-Z1W-R1-05 | I6: POD-05 | J6: ="RACKPDU-"&H6&"-A" -> RACKPDU-RACK-R3-Z1W-R1-05-A | K6: ="RACKPDU-"&H6&"-B" -> RACKPDU-RACK-R3-Z1W-R1-05-B | L6: 30 | M6: =VLOOKUP($H6,'Cooling-Rack'!$A$2:$G$265,5,FALSE) -> 22.5 | N6: =VLOOKUP($H6,'Cooling-Rack'!$A$2:$G$265,7,FALSE) -> 7.5 | O6: 36 | P6: 0.75 | Q6: 0.25 | R6: RPP-R3-A2 | S6: RPP-R3-B2 | T6: RPDU-R3-A | U6: RPDU-R3R4-B | V6: UPS-02-A | W6: UPS-02-B | X6: BESS-01 | Y6: SWGR-01 | Z6: SWGR-02 | AA6: UTIL-01 | AB6: UTIL-02 | AC6: GEN-01 | AD6: GEN-02 | AE6: CC-R3 | AF6: BDL-R3 | AG6: BDL-RPDU-R3R4 | AH6: BDL-UPS-02 | AL6: 30 | AM6: =AL6/$L6*$M6 -> 22.5 | AN6: =AL6/$L6*$N6 -> 7.5 | AO6: 30 | AP6: =AO6/$L6*$M6 -> 22.5 | AQ6: =AO6/$L6*$N6 -> 7.5 | BA6: =$L6-$AI6 -> 30 | BB6: =$L6-$AL6 -> 0 | BC6: =$L6-$AO6 -> 0 | BD6: =$L6-$AR6 -> 30 | BE6: =$L6-$AU6 -> 30 | BF6: =$L6-$AX6 -> 30 | BG6: =BA6/$L6 -> 1 | BH6: =BB6/$L6 -> 0 | BI6: =BC6/$L6 -> 0 | BJ6: =BD6/$L6 -> 1 | BK6: =BE6/$L6 -> 1 | BL6: =BF6/$L6 -> 1 | BO6: DTC-RACK-R3-Z1W-R1-05 | BP6: =M6/0.9 -> 25 | BQ6: =IF($AI6>0, 1, 0) -> 0 | BR6: =IF($AL6>0, 1, 0) -> 1 | BS6: =IF($AO6>0, 1, 0) -> 1 | BT6: =IF($AR6>0, 1, 0) -> 0 | BU6: =IF($AU6>0, 1, 0) -> 0 | BV6: =IF(AX6>0, 1, 0) -> 0
A7: ZONE-R3-Z1W | B7: ROW-R3-Z1W-R1 | C7: 30 | F7: LL-R3-W | G7: AIRZONE-R3-W1 | H7: RACK-R3-Z1W-R1-06 | I7: POD-05 | J7: ="RACKPDU-"&H7&"-A" -> RACKPDU-RACK-R3-Z1W-R1-06-A | K7: ="RACKPDU-"&H7&"-B" -> RACKPDU-RACK-R3-Z1W-R1-06-B | L7: 30 | M7: =VLOOKUP($H7,'Cooling-Rack'!$A$2:$G$265,5,FALSE) -> 22.5 | N7: =VLOOKUP($H7,'Cooling-Rack'!$A$2:$G$265,7,FALSE) -> 7.5 | O7: 36 | P7: 0.75 | Q7: 0.25 | R7: RPP-R3-A2 | S7: RPP-R3-B2 | T7: RPDU-R3-A | U7: RPDU-R3R4-B | V7: UPS-02-A | W7: UPS-02-B | X7: BESS-01 | Y7: SWGR-01 | Z7: SWGR-02 | AA7: UTIL-01 | AB7: UTIL-02 | AC7: GEN-01 | AD7: GEN-02 | AE7: CC-R3 | AF7: BDL-R3 | AG7: BDL-RPDU-R3R4 | AH7: BDL-UPS-02 | AL7: 30 | AM7: =AL7/$L7*$M7 -> 22.5 | AN7: =AL7/$L7*$N7 -> 7.5 | AO7: 30 | AP7: =AO7/$L7*$M7 -> 22.5 | AQ7: =AO7/$L7*$N7 -> 7.5 | BA7: =$L7-$AI7 -> 30 | BB7: =$L7-$AL7 -> 0 | BC7: =$L7-$AO7 -> 0 | BD7: =$L7-$AR7 -> 30 | BE7: =$L7-$AU7 -> 30 | BF7: =$L7-$AX7 -> 30 | BG7: =BA7/$L7 -> 1 | BH7: =BB7/$L7 -> 0 | BI7: =BC7/$L7 -> 0 | BJ7: =BD7/$L7 -> 1 | BK7: =BE7/$L7 -> 1 | BL7: =BF7/$L7 -> 1 | BO7: DTC-RACK-R3-Z1W-R1-06 | BP7: =M7/0.9 -> 25 | BQ7: =IF($AI7>0, 1, 0) -> 0 | BR7: =IF($AL7>0, 1, 0) -> 1 | BS7: =IF($AO7>0, 1, 0) -> 1 | BT7: =IF($AR7>0, 1, 0) -> 0 | BU7: =IF($AU7>0, 1, 0) -> 0 | BV7: =IF(AX7>0, 1, 0) -> 0
A8: ZONE-R3-Z1W | B8: ROW-R3-Z1W-R1 | C8: 30 | F8: LL-R3-W | G8: AIRZONE-R3-W1 | H8: RACK-R3-Z1W-R1-07 | I8: POD-05 | J8: ="RACKPDU-"&H8&"-A" -> RACKPDU-RACK-R3-Z1W-R1-07-A | K8: ="RACKPDU-"&H8&"-B" -> RACKPDU-RACK-R3-Z1W-R1-07-B | L8: 30 | M8: =VLOOKUP($H8,'Cooling-Rack'!$A$2:$G$265,5,FALSE) -> 22.5 | N8: =VLOOKUP($H8,'Cooling-Rack'!$A$2:$G$265,7,FALSE) -> 7.5 | O8: 36 | P8: 0.75 | Q8: 0.25 | R8: RPP-R3-A2 | S8: RPP-R3-B3 | T8: RPDU-R3-A | U8: RPDU-R3-B | V8: UPS-02-A | W8: UPS-02-B | X8: BESS-01 | Y8: SWGR-01 | Z8: SWGR-02 | AA8: UTIL-01 | AB8: UTIL-02 | AC8: GEN-01 | AD8: GEN-02 | AE8: CC-R3 | AF8: BDL-R3 | AG8: BDL-RPDU-R3R4 | AH8: BDL-UPS-02 | AL8: 30 | AM8: =AL8/$L8*$M8 -> 22.5 | AN8: =AL8/$L8*$N8 -> 7.5 | AO8: 30 | AP8: =AO8/$L8*$M8 -> 22.5 | AQ8: =AO8/$L8*$N8 -> 7.5 | BA8: =$L8-$AI8 -> 30 | BB8: =$L8-$AL8 -> 0 | BC8: =$L8-$AO8 -> 0 | BD8: =$L8-$AR8 -> 30 | BE8: =$L8-$AU8 -> 30 | BF8: =$L8-$AX8 -> 30 | BG8: =BA8/$L8 -> 1 | BH8: =BB8/$L8 -> 0 | BI8: =BC8/$L8 -> 0 | BJ8: =BD8/$L8 -> 1 | BK8: =BE8/$L8 -> 1 | BL8: =BF8/$L8 -> 1 | BO8: DTC-RACK-R3-Z1W-R1-07 | BP8: =M8/0.9 -> 25 | BQ8: =IF($AI8>0, 1, 0) -> 0 | BR8: =IF($AL8>0, 1, 0) -> 1 | BS8: =IF($AO8>0, 1, 0) -> 1 | BT8: =IF($AR8>0, 1, 0) -> 0 | BU8: =IF($AU8>0, 1, 0) -> 0 | BV8: =IF(AX8>0, 1, 0) -> 0
A9: ZONE-R3-Z1W | B9: ROW-R3-Z1W-R1 | C9: 30 | F9: LL-R3-W | G9: AIRZONE-R3-W1 | H9: RACK-R3-Z1W-R1-08 | I9: POD-05 | J9: ="RACKPDU-"&H9&"-A" -> RACKPDU-RACK-R3-Z1W-R1-08-A | K9: ="RACKPDU-"&H9&"-B" -> RACKPDU-RACK-R3-Z1W-R1-08-B | L9: 30 | M9: =VLOOKUP($H9,'Cooling-Rack'!$A$2:$G$265,5,FALSE) -> 22.5 | N9: =VLOOKUP($H9,'Cooling-Rack'!$A$2:$G$265,7,FALSE) -> 7.5 | O9: 36 | P9: 0.75 | Q9: 0.25 | R9: RPP-R3-A2 | S9: RPP-R3-B3 | T9: RPDU-R3-A | U9: RPDU-R3-B | V9: UPS-02-A | W9: UPS-02-B | X9: BESS-01 | Y9: SWGR-01 | Z9: SWGR-02 | AA9: UTIL-01 | AB9: UTIL-02 | AC9: GEN-01 | AD9: GEN-02 | AE9: CC-R3 | AF9: BDL-R3 | AG9: BDL-RPDU-R3R4 | AH9: BDL-UPS-02 | AL9: 30 | AM9: =AL9/$L9*$M9 -> 22.5 | AN9: =AL9/$L9*$N9 -> 7.5 | AO9: 30 | AP9: =AO9/$L9*$M9 -> 22.5 | AQ9: =AO9/$L9*$N9 -> 7.5 | BA9: =$L9-$AI9 -> 30 | BB9: =$L9-$AL9 -> 0 | BC9: =$L9-$AO9 -> 0 | BD9: =$L9-$AR9 -> 30 | BE9: =$L9-$AU9 -> 30 | BF9: =$L9-$AX9 -> 30 | BG9: =BA9/$L9 -> 1 | BH9: =BB9/$L9 -> 0 | BI9: =BC9/$L9 -> 0 | BJ9: =BD9/$L9 -> 1 | BK9: =BE9/$L9 -> 1 | BL9: =BF9/$L9 -> 1 | BO9: DTC-RACK-R3-Z1W-R1-08 | BP9: =M9/0.9 -> 25 | BQ9: =IF($AI9>0, 1, 0) -> 0 | BR9: =IF($AL9>0, 1, 0) -> 1 | BS9: =IF($AO9>0, 1, 0) -> 1 | BT9: =IF($AR9>0, 1, 0) -> 0 | BU9: =IF($AU9>0, 1, 0) -> 0 | BV9: =IF(AX9>0, 1, 0) -> 0
A10: ZONE-R3-Z1W | B10: ROW-R3-Z1W-R1 | C10: 30 | F10: LL-R3-W | G10: AIRZONE-R3-W1 | H10: RACK-R3-Z1W-R1-09 | I10: POD-05 | J10: ="RACKPDU-"&H10&"-A" -> RACKPDU-RACK-R3-Z1W-R1-09-A | K10: ="RACKPDU-"&H10&"-B" -> RACKPDU-RACK-R3-Z1W-R1-09-B | L10: 30 | M10: =VLOOKUP($H10,'Cooling-Rack'!$A$2:$G$265,5,FALSE) -> 22.5 | N10: =VLOOKUP($H10,'Cooling-Rack'!$A$2:$G$265,7,FALSE) -> 7.5 | O10: 36 | P10: 0.75 | Q10: 0.25 | R10: RPP-R3-A1 | S10: RPP-R3-B3 | T10: RPDU-R3-A | U10: RPDU-R3-B | V10: UPS-02-A | W10: UPS-02-B | X10: BESS-01 | Y10: SWGR-01 | Z10: SWGR-02 | AA10: UTIL-01 | AB10: UTIL-02 | AC10: GEN-01 | AD10: GEN-02 | AE10: CC-R3 | AF10: BDL-R3 | AG10: BDL-RPDU-R3R4 | AH10: BDL-UPS-02 | AL10: 30 | AM10: =AL10/$L10*$M10 -> 22.5 | AN10: =AL10/$L10*$N10 -> 7.5 | AO10: 0 | AP10: =AO10/$L10*$M10 -> 0 | AQ10: =AO10/$L10*$N10 -> 0 | BA10: =$L10-$AI10 -> 30 | BB10: =$L10-$AL10 -> 0 | BC10: =$L10-$AO10 -> 30 | BD10: =$L10-$AR10 -> 30 | BE10: =$L10-$AU10 -> 30 | BF10: =$L10-$AX10 -> 30 | BG10: =BA10/$L10 -> 1 | BH10: =BB10/$L10 -> 0 | BI10: =BC10/$L10 -> 1 | BJ10: =BD10/$L10 -> 1 | BK10: =BE10/$L10 -> 1 | BL10: =BF10/$L10 -> 1 | BO10: DTC-RACK-R3-Z1W-R1-09 | BP10: =M10/0.9 -> 25 | BQ10: =IF($AI10>0, 1, 0) -> 0 | BR10: =IF($AL10>0, 1, 0) -> 1 | BS10: =IF($AO10>0, 1, 0) -> 0 | BT10: =IF($AR10>0, 1, 0) -> 0 | BU10: =IF($AU10>0, 1, 0) -> 0 | BV10: =IF(AX10>0, 1, 0) -> 0
A11: ZONE-R3-Z1W | B11: ROW-R3-Z1W-R1 | C11: 30 | F11: LL-R3-W | G11: AIRZONE-R3-W1 | H11: RACK-R3-Z1W-R1-10 | I11: POD-05 | J11: ="RACKPDU-"&H11&"-A" -> RACKPDU-RACK-R3-Z1W-R1-10-A | K11: ="RACKPDU-"&H11&"-B" -> RACKPDU-RACK-R3-Z1W-R1-10-B | L11: 30 | M11: =VLOOKUP($H11,'Cooling-Rack'!$A$2:$G$265,5,FALSE) -> 22.5 | N11: =VLOOKUP($H11,'Cooling-Rack'!$A$2:$G$265,7,FALSE) -> 7.5 | O11: 36 | P11: 0.75 | Q11: 0.25 | R11: RPP-R3-A1 | S11: RPP-R3-B3 | T11: RPDU-R3-A | U11: RPDU-R3-B | V11: UPS-02-A | W11: UPS-02-B | X11: BESS-01 | Y11: SWGR-01 | Z11: SWGR-02 | AA11: UTIL-01 | AB11: UTIL-02 | AC11: GEN-01 | AD11: GEN-02 | AE11: CC-R3 | AF11: BDL-R3 | AG11: BDL-RPDU-R3R4 | AH11: BDL-UPS-02 | AL11: 30 | AM11: =AL11/$L11*$M11 -> 22.5 | AN11: =AL11/$L11*$N11 -> 7.5 | AO11: 0 | AP11: =AO11/$L11*$M11 -> 0 | AQ11: =AO11/$L11*$N11 -> 0 | BA11: =$L11-$AI11 -> 30 | BB11: =$L11-$AL11 -> 0 | BC11: =$L11-$AO11 -> 30 | BD11: =$L11-$AR11 -> 30 | BE11: =$L11-$AU11 -> 30 | BF11: =$L11-$AX11 -> 30 | BG11: =BA11/$L11 -> 1 | BH11: =BB11/$L11 -> 0 | BI11: =BC11/$L11 -> 1 | BJ11: =BD11/$L11 -> 1 | BK11: =BE11/$L11 -> 1 | BL11: =BF11/$L11 -> 1 | BO11: DTC-RACK-R3-Z1W-R1-10 | BP11: =M11/0.9 -> 25 | BQ11: =IF($AI11>0, 1, 0) -> 0 | BR11: =IF($AL11>0, 1, 0) -> 1 | BS11: =IF($AO11>0, 1, 0) -> 0 | BT11: =IF($AR11>0, 1, 0) -> 0 | BU11: =IF($AU11>0, 1, 0) -> 0 | BV11: =IF(AX11>0, 1, 0) -> 0
A12: ZONE-R3-Z1W | B12: ROW-R3-Z1W-R1 | C12: 30 | F12: LL-R3-W | G12: AIRZONE-R3-W1 | H12: RACK-R3-Z1W-R1-11 | I12: POD-05 | J12: ="RACKPDU-"&H12&"-A" -> RACKPDU-RACK-R3-Z1W-R1-11-A | K12: ="RACKPDU-"&H12&"-B" -> RACKPDU-RACK-R3-Z1W-R1-11-B | L12: 30 | M12: =VLOOKUP($H12,'Cooling-Rack'!$A$2:$G$265,5,FALSE) -> 22.5 | N12: =VLOOKUP($H12,'Cooling-Rack'!$A$2:$G$265,7,FALSE) -> 7.5 | O12: 36 | P12: 0.75 | Q12: 0.25 | R12: RPP-R3-A1 | S12: RPP-R3-B3 | T12: RPDU-R3-A | U12: RPDU-R3-B | V12: UPS-02-A | W12: UPS-02-B | X12: BESS-01 | Y12: SWGR-01 | Z12: SWGR-02 | AA12: UTIL-01 | AB12: UTIL-02 | AC12: GEN-01 | AD12: GEN-02 | AE12: CC-R3 | AF12: BDL-R3 | AG12: BDL-RPDU-R3R4 | AH12: BDL-UPS-02 | AL12: 30 | AM12: =AL12/$L12*$M12 -> 22.5 | AN12: =AL12/$L12*$N12 -> 7.5 | AO12: 0 | AP12: =AO12/$L12*$M12 -> 0 | AQ12: =AO12/$L12*$N12 -> 0 | BA12: =$L12-$AI12 -> 30 | BB12: =$L12-$AL12 -> 0 | BC12: =$L12-$AO12 -> 30 | BD12: =$L12-$AR12 -> 30 | BE12: =$L12-$AU12 -> 30 | BF12: =$L12-$AX12 -> 30 | BG12: =BA12/$L12 -> 1 | BH12: =BB12/$L12 -> 0 | BI12: =BC12/$L12 -> 1 | BJ12: =BD12/$L12 -> 1 | BK12: =BE12/$L12 -> 1 | BL12: =BF12/$L12 -> 1 | BO12: DTC-RACK-R3-Z1W-R1-11 | BP12: =M12/0.9 -> 25 | BQ12: =IF($AI12>0, 1, 0) -> 0 | BR12: =IF($AL12>0, 1, 0) -> 1 | BS12: =IF($AO12>0, 1, 0) -> 0 | BT12: =IF($AR12>0, 1, 0) -> 0 | BU12: =IF($AU12>0, 1, 0) -> 0 | BV12: =IF(AX12>0, 1, 0) -> 0
A13: ZONE-R3-Z1W | B13: ROW-R3-Z1W-R1 | C13: 30 | F13: LL-R3-W | G13: AIRZONE-R3-W1 | H13: RACK-R3-Z1W-R1-12 | I13: POD-05 | J13: ="RACKPDU-"&H13&"-A" -> RACKPDU-RACK-R3-Z1W-R1-12-A | K13: ="RACKPDU-"&H13&"-B" -> RACKPDU-RACK-R3-Z1W-R1-12-B | L13: 30 | M13: =VLOOKUP($H13,'Cooling-Rack'!$A$2:$G$265,5,FALSE) -> 22.5 | N13: =VLOOKUP($H13,'Cooling-Rack'!$A$2:$G$265,7,FALSE) -> 7.5 | O13: 36 | P13: 0.75 | Q13: 0.25 | R13: RPP-R3-A1 | S13: RPP-R3-B3 | T13: RPDU-R3-A | U13: RPDU-R3-B | V13: UPS-02-A | W13: UPS-02-B | X13: BESS-01 | Y13: SWGR-01 | Z13: SWGR-02 | AA13: UTIL-01 | AB13: UTIL-02 | AC13: GEN-01 | AD13: GEN-02 | AE13: CC-R3 | AF13: BDL-R3 | AG13: BDL-RPDU-R3R4 | AH13: BDL-UPS-02 | AL13: 30 | AM13: =AL13/$L13*$M13 -> 22.5 | AN13: =AL13/$L13*$N13 -> 7.5 | AO13: 0 | AP13: =AO13/$L13*$M13 -> 0 | AQ13: =AO13/$L13*$N13 -> 0 | BA13: =$L13-$AI13 -> 30 | BB13: =$L13-$AL13 -> 0 | BC13: =$L13-$AO13 -> 30 | BD13: =$L13-$AR13 -> 30 | BE13: =$L13-$AU13 -> 30 | BF13: =$L13-$AX13 -> 30 | BG13: =BA13/$L13 -> 1 | BH13: =BB13/$L13 -> 0 | BI13: =BC13/$L13 -> 1 | BJ13: =BD13/$L13 -> 1 | BK13: =BE13/$L13 -> 1 | BL13: =BF13/$L13 -> 1 | BO13: DTC-RACK-R3-Z1W-R1-12 | BP13: =M13/0.9 -> 25 | BQ13: =IF($AI13>0, 1, 0) -> 0 | BR13: =IF($AL13>0, 1, 0) -> 1 | BS13: =IF($AO13>0, 1, 0) -> 0 | BT13: =IF($AR13>0, 1, 0) -> 0 | BU13: =IF($AU13>0, 1, 0) -> 0 | BV13: =IF(AX13>0, 1, 0) -> 0
... A73: ZONE-R3-Z3W | B73: ROW-R3-Z3W-R2 | C73: 30 | F73: LL-R3-W | G73: AIRZONE-R3-W2 | H73: RACK-R3-Z3W-R2-12 | I73: POD-05 | J73: ="RACKPDU-"&H73&"-A" -> RACKPDU-RACK-R3-Z3W-R2-12-A | K73: ="RACKPDU-"&H73&"-B" -> RACKPDU-RACK-R3-Z3W-R2-12-B | L73: 30 | M73: =VLOOKUP($H73,'Cooling-Rack'!$A$2:$G$265,5,FALSE) -> 22.5 | N73: =VLOOKUP($H73,'Cooling-Rack'!$A$2:$G$265,7,FALSE) -> 7.5 | O73: 36 | P73: 0.75 | Q73: 0.25 | R73: RPP-R3-A2 | S73: RPP-R3-B3 | T73: RPDU-R3-A | U73: RPDU-R3-B | V73: UPS-02-A | W73: UPS-02-B | X73: BESS-01 | Y73: SWGR-01 | Z73: SWGR-02 | AA73: UTIL-01 | AB73: UTIL-02 | AC73: GEN-01 | AD73: GEN-02 | AE73: CC-R3 | AF73: BDL-R3 | AG73: BDL-RPDU-R3R4 | AH73: BDL-UPS-02 | AL73: 0 | AM73: =AL73/$L73*$M73 -> 0 | AN73: =AL73/$L73*$N73 -> 0 | AO73: 0 | AP73: =AO73/$L73*$M73 -> 0 | AQ73: =AO73/$L73*$N73 -> 0 | BA73: =$L73-$AI73 -> 30 | BB73: =$L73-$AL73 -> 30 | BC73: =$L73-$AO73 -> 30 | BD73: =$L73-$AR73 -> 30 | BE73: =$L73-$AU73 -> 30 | BF73: =$L73-$AX73 -> 30 | BG73: =BA73/$L73 -> 1 | BH73: =BB73/$L73 -> 1 | BI73: =BC73/$L73 -> 1 | BJ73: =BD73/$L73 -> 1 | BK73: =BE73/$L73 -> 1 | BL73: =BF73/$L73 -> 1 | BO73: DTC-RACK-R3-Z3W-R2-12 | BP73: =M73/0.9 -> 25 | BQ73: =IF($AI73>0, 1, 0) -> 0 | BR73: =IF($AL73>0, 1, 0) -> 0 | BS73: =IF($AO73>0, 1, 0) -> 0 | BT73: =IF($AR73>0, 1, 0) -> 0 | BU73: =IF($AU73>0, 1, 0) -> 0 | BV73: =IF(AX73>0, 1, 0) -> 0
A74: ZONE-R3-Z4E | B74: ROW-R3-Z4E-R1 | C74: 45 | F74: LL-R3-E | G74: AIRZONE-R3-E1 | H74: RACK-R3-Z4E-R1-01 | I74: POD-06 | J74: ="RACKPDU-"&H74&"-A" -> RACKPDU-RACK-R3-Z4E-R1-01-A | K74: ="RACKPDU-"&H74&"-B" -> RACKPDU-RACK-R3-Z4E-R1-01-B | L74: 45 | M74: =VLOOKUP($H74,'Cooling-Rack'!$A$2:$G$265,5,FALSE) -> 38.25 | N74: =VLOOKUP($H74,'Cooling-Rack'!$A$2:$G$265,7,FALSE) -> 6.75 | O74: 54 | P74: 0.85 | Q74: 0.15 | R74: RPP-R3-A1 | S74: RPP-R3-B1 | T74: RPDU-R3-A | U74: RPDU-R3R4-B | V74: UPS-02-A | W74: UPS-02-B | X74: BESS-01 | Y74: SWGR-01 | Z74: SWGR-02 | AA74: UTIL-01 | AB74: UTIL-02 | AC74: GEN-01 | AD74: GEN-02 | AE74: CC-R3 | AF74: BDL-R3 | AG74: BDL-RPDU-R3R4 | AH74: BDL-UPS-02 | AL74: 0 | AM74: =AL74/$L74*$M74 -> 0 | AN74: =AL74/$L74*$N74 -> 0 | AO74: 0 | AP74: =AO74/$L74*$M74 -> 0 | AQ74: =AO74/$L74*$N74 -> 0 | AS74: =AR74/$L74*$M74 -> 0 | AT74: =AR74/$L74*$N74 -> 0 | AU74: 30 | AV74: =AU74/$L74*$M74 -> 25.5 | AW74: =AU74/$L74*$N74 -> 4.5 | BA74: =$L74-$AI74 -> 45 | BB74: =$L74-$AL74 -> 45 | BC74: =$L74-$AO74 -> 45 | BD74: =$L74-$AR74 -> 45 | BE74: =$L74-$AU74 -> 15 | BF74: =$L74-$AX74 -> 45 | BG74: =BA74/$L74 -> 1 | BH74: =BB74/$L74 -> 1 | BI74: =BC74/$L74 -> 1 | BJ74: =BD74/$L74 -> 1 | BK74: =BE74/$L74 -> 0.33333333 | BL74: =BF74/$L74 -> 1 | BO74: DTC-RACK-R3-Z4E-R1-01 | BP74: =M74/0.9 -> 42.5 | BQ74: =IF($AI74>0, 1, 0) -> 0 | BR74: =IF($AL74>0, 1, 0) -> 0 | BS74: =IF($AO74>0, 1, 0) -> 0 | BT74: =IF($AR74>0, 1, 0) -> 0 | BU74: =IF($AU74>0, 1, 0) -> 1 | BV74: =IF(AX74>0, 1, 0) -> 0
A75: ZONE-R3-Z4E | B75: ROW-R3-Z4E-R1 | C75: 45 | F75: LL-R3-E | G75: AIRZONE-R3-E1 | H75: RACK-R3-Z4E-R1-02 | I75: POD-06 | J75: ="RACKPDU-"&H75&"-A" -> RACKPDU-RACK-R3-Z4E-R1-02-A | K75: ="RACKPDU-"&H75&"-B" -> RACKPDU-RACK-R3-Z4E-R1-02-B | L75: 45 | M75: =VLOOKUP($H75,'Cooling-Rack'!$A$2:$G$265,5,FALSE) -> 38.25 | N75: =VLOOKUP($H75,'Cooling-Rack'!$A$2:$G$265,7,FALSE) -> 6.75 | O75: 54 | P75: 0.85 | Q75: 0.15 | R75: RPP-R3-A1 | S75: RPP-R3-B1 | T75: RPDU-R3-A | U75: RPDU-R3R4-B | V75: UPS-02-A | W75: UPS-02-B | X75: BESS-01 | Y75: SWGR-01 | Z75: SWGR-02 | AA75: UTIL-01 | AB75: UTIL-02 | AC75: GEN-01 | AD75: GEN-02 | AE75: CC-R3 | AF75: BDL-R3 | AG75: BDL-RPDU-R3R4 | AH75: BDL-UPS-02 | AL75: 0 | AM75: =AL75/$L75*$M75 -> 0 | AN75: =AL75/$L75*$N75 -> 0 | AO75: 0 | AP75: =AO75/$L75*$M75 -> 0 | AQ75: =AO75/$L75*$N75 -> 0 | AS75: =AR75/$L75*$M75 -> 0 | AT75: =AR75/$L75*$N75 -> 0 | AU75: 30 | AV75: =AU75/$L75*$M75 -> 25.5 | AW75: =AU75/$L75*$N75 -> 4.5 | BA75: =$L75-$AI75 -> 45 | BB75: =$L75-$AL75 -> 45 | BC75: =$L75-$AO75 -> 45 | BD75: =$L75-$AR75 -> 45 | BE75: =$L75-$AU75 -> 15 | BF75: =$L75-$AX75 -> 45 | BG75: =BA75/$L75 -> 1 | BH75: =BB75/$L75 -> 1 | BI75: =BC75/$L75 -> 1 | BJ75: =BD75/$L75 -> 1 | BK75: =BE75/$L75 -> 0.33333333 | BL75: =BF75/$L75 -> 1 | BO75: DTC-RACK-R3-Z4E-R1-02 | BP75: =M75/0.9 -> 42.5 | BQ75: =IF($AI75>0, 1, 0) -> 0 | BR75: =IF($AL75>0, 1, 0) -> 0 | BS75: =IF($AO75>0, 1, 0) -> 0 | BT75: =IF($AR75>0, 1, 0) -> 0 | BU75: =IF($AU75>0, 1, 0) -> 1 | BV75: =IF(AX75>0, 1, 0) -> 0
A76: ZONE-R3-Z4E | B76: ROW-R3-Z4E-R1 | C76: 45 | F76: LL-R3-E | G76: AIRZONE-R3-E1 | H76: RACK-R3-Z4E-R1-03 | I76: POD-06 | J76: ="RACKPDU-"&H76&"-A" -> RACKPDU-RACK-R3-Z4E-R1-03-A | K76: ="RACKPDU-"&H76&"-B" -> RACKPDU-RACK-R3-Z4E-R1-03-B | L76: 45 | M76: =VLOOKUP($H76,'Cooling-Rack'!$A$2:$G$265,5,FALSE) -> 38.25 | N76: =VLOOKUP($H76,'Cooling-Rack'!$A$2:$G$265,7,FALSE) -> 6.75 | O76: 54 | P76: 0.85 | Q76: 0.15 | R76: RPP-R3-A1 | S76: RPP-R3-B1 | T76: RPDU-R3-A | U76: RPDU-R3R4-B | V76: UPS-02-A | W76: UPS-02-B | X76: BESS-01 | Y76: SWGR-01 | Z76: SWGR-02 | AA76: UTIL-01 | AB76: UTIL-02 | AC76: GEN-01 | AD76: GEN-02 | AE76: CC-R3 | AF76: BDL-R3 | AG76: BDL-RPDU-R3R4 | AH76: BDL-UPS-02 | AL76: 0 | AM76: =AL76/$L76*$M76 -> 0 | AN76: =AL76/$L76*$N76 -> 0 | AO76: 0 | AP76: =AO76/$L76*$M76 -> 0 | AQ76: =AO76/$L76*$N76 -> 0 | AS76: =AR76/$L76*$M76 -> 0 | AT76: =AR76/$L76*$N76 -> 0 | AU76: 30 | AV76: =AU76/$L76*$M76 -> 25.5 | AW76: =AU76/$L76*$N76 -> 4.5 | BA76: =$L76-$AI76 -> 45 | BB76: =$L76-$AL76 -> 45 | BC76: =$L76-$AO76 -> 45 | BD76: =$L76-$AR76 -> 45 | BE76: =$L76-$AU76 -> 15 | BF76: =$L76-$AX76 -> 45 | BG76: =BA76/$L76 -> 1 | BH76: =BB76/$L76 -> 1 | BI76: =BC76/$L76 -> 1 | BJ76: =BD76/$L76 -> 1 | BK76: =BE76/$L76 -> 0.33333333 | BL76: =BF76/$L76 -> 1 | BO76: DTC-RACK-R3-Z4E-R1-03 | BP76: =M76/0.9 -> 42.5 | BQ76: =IF($AI76>0, 1, 0) -> 0 | BR76: =IF($AL76>0, 1, 0) -> 0 | BS76: =IF($AO76>0, 1, 0) -> 0 | BT76: =IF($AR76>0, 1, 0) -> 0 | BU76: =IF($AU76>0, 1, 0) -> 1 | BV76: =IF(AX76>0, 1, 0) -> 0
A77: ZONE-R3-Z4E | B77: ROW-R3-Z4E-R1 | C77: 45 | F77: LL-R3-E | G77: AIRZONE-R3-E1 | H77: RACK-R3-Z4E-R1-04 | I77: POD-06 | J77: ="RACKPDU-"&H77&"-A" -> RACKPDU-RACK-R3-Z4E-R1-04-A | K77: ="RACKPDU-"&H77&"-B" -> RACKPDU-RACK-R3-Z4E-R1-04-B | L77: 45 | M77: =VLOOKUP($H77,'Cooling-Rack'!$A$2:$G$265,5,FALSE) -> 38.25 | N77: =VLOOKUP($H77,'Cooling-Rack'!$A$2:$G$265,7,FALSE) -> 6.75 | O77: 54 | P77: 0.85 | Q77: 0.15 | R77: RPP-R3-A1 | S77: RPP-R3-B1 | T77: RPDU-R3-A | U77: RPDU-R3R4-B | V77: UPS-02-A | W77: UPS-02-B | X77: BESS-01 | Y77: SWGR-01 | Z77: SWGR-02 | AA77: UTIL-01 | AB77: UTIL-02 | AC77: GEN-01 | AD77: GEN-02 | AE77: CC-R3 | AF77: BDL-R3 | AG77: BDL-RPDU-R3R4 | AH77: BDL-UPS-02 | AL77: 0 | AM77: =AL77/$L77*$M77 -> 0 | AN77: =AL77/$L77*$N77 -> 0 | AO77: 0 | AP77: =AO77/$L77*$M77 -> 0 | AQ77: =AO77/$L77*$N77 -> 0 | AS77: =AR77/$L77*$M77 -> 0 | AT77: =AR77/$L77*$N77 -> 0 | AU77: 30 | AV77: =AU77/$L77*$M77 -> 25.5 | AW77: =AU77/$L77*$N77 -> 4.5 | BA77: =$L77-$AI77 -> 45 | BB77: =$L77-$AL77 -> 45 | BC77: =$L77-$AO77 -> 45 | BD77: =$L77-$AR77 -> 45 | BE77: =$L77-$AU77 -> 15 | BF77: =$L77-$AX77 -> 45 | BG77: =BA77/$L77 -> 1 | BH77: =BB77/$L77 -> 1 | BI77: =BC77/$L77 -> 1 | BJ77: =BD77/$L77 -> 1 | BK77: =BE77/$L77 -> 0.33333333 | BL77: =BF77/$L77 -> 1 | BO77: DTC-RACK-R3-Z4E-R1-04 | BP77: =M77/0.9 -> 42.5 | BQ77: =IF($AI77>0, 1, 0) -> 0 | BR77: =IF($AL77>0, 1, 0) -> 0 | BS77: =IF($AO77>0, 1, 0) -> 0 | BT77: =IF($AR77>0, 1, 0) -> 0 | BU77: =IF($AU77>0, 1, 0) -> 1 | BV77: =IF(AX77>0, 1, 0) -> 0
A78: ZONE-R3-Z4E | B78: ROW-R3-Z4E-R1 | C78: 45 | F78: LL-R3-E | G78: AIRZONE-R3-E1 | H78: RACK-R3-Z4E-R1-05 | I78: POD-06 | J78: ="RACKPDU-"&H78&"-A" -> RACKPDU-RACK-R3-Z4E-R1-05-A | K78: ="RACKPDU-"&H78&"-B" -> RACKPDU-RACK-R3-Z4E-R1-05-B | L78: 45 | M78: =VLOOKUP($H78,'Cooling-Rack'!$A$2:$G$265,5,FALSE) -> 38.25 | N78: =VLOOKUP($H78,'Cooling-Rack'!$A$2:$G$265,7,FALSE) -> 6.75 | O78: 54 | P78: 0.85 | Q78: 0.15 | R78: RPP-R3-A3 | S78: RPP-R3-B1 | T78: RPDU-R3-A | U78: RPDU-R3R4-B | V78: UPS-02-A | W78: UPS-02-B | X78: BESS-01 | Y78: SWGR-01 | Z78: SWGR-02 | AA78: UTIL-01 | AB78: UTIL-02 | AC78: GEN-01 | AD78: GEN-02 | AE78: CC-R3 | AF78: BDL-R3 | AG78: BDL-RPDU-R3R4 | AH78: BDL-UPS-02 | AL78: 0 | AM78: =AL78/$L78*$M78 -> 0 | AN78: =AL78/$L78*$N78 -> 0 | AO78: 0 | AP78: =AO78/$L78*$M78 -> 0 | AQ78: =AO78/$L78*$N78 -> 0 | AR78: 30 | AS78: =AR78/$L78*$M78 -> 25.5 | AT78: =AR78/$L78*$N78 -> 4.5 | AU78: 30 | AV78: =AU78/$L78*$M78 -> 25.5 | AW78: =AU78/$L78*$N78 -> 4.5 | BA78: =$L78-$AI78 -> 45 | BB78: =$L78-$AL78 -> 45 | BC78: =$L78-$AO78 -> 45 | BD78: =$L78-$AR78 -> 15 | BE78: =$L78-$AU78 -> 15 | BF78: =$L78-$AX78 -> 45 | BG78: =BA78/$L78 -> 1 | BH78: =BB78/$L78 -> 1 | BI78: =BC78/$L78 -> 1 | BJ78: =BD78/$L78 -> 0.33333333 | BK78: =BE78/$L78 -> 0.33333333 | BL78: =BF78/$L78 -> 1 | BO78: DTC-RACK-R3-Z4E-R1-05 | BP78: =M78/0.9 -> 42.5 | BQ78: =IF($AI78>0, 1, 0) -> 0 | BR78: =IF($AL78>0, 1, 0) -> 0 | BS78: =IF($AO78>0, 1, 0) -> 0 | BT78: =IF($AR78>0, 1, 0) -> 1 | BU78: =IF($AU78>0, 1, 0) -> 1 | BV78: =IF(AX78>0, 1, 0) -> 0
A79: ZONE-R3-Z4E | B79: ROW-R3-Z4E-R1 | C79: 45 | F79: LL-R3-E | G79: AIRZONE-R3-E1 | H79: RACK-R3-Z4E-R1-06 | I79: POD-06 | J79: ="RACKPDU-"&H79&"-A" -> RACKPDU-RACK-R3-Z4E-R1-06-A | K79: ="RACKPDU-"&H79&"-B" -> RACKPDU-RACK-R3-Z4E-R1-06-B | L79: 45 | M79: =VLOOKUP($H79,'Cooling-Rack'!$A$2:$G$265,5,FALSE) -> 38.25 | N79: =VLOOKUP($H79,'Cooling-Rack'!$A$2:$G$265,7,FALSE) -> 6.75 | O79: 54 | P79: 0.85 | Q79: 0.15 | R79: RPP-R3-A3 | S79: RPP-R3-B1 | T79: RPDU-R3-A | U79: RPDU-R3R4-B | V79: UPS-02-A | W79: UPS-02-B | X79: BESS-01 | Y79: SWGR-01 | Z79: SWGR-02 | AA79: UTIL-01 | AB79: UTIL-02 | AC79: GEN-01 | AD79: GEN-02 | AE79: CC-R3 | AF79: BDL-R3 | AG79: BDL-RPDU-R3R4 | AH79: BDL-UPS-02 | AL79: 0 | AM79: =AL79/$L79*$M79 -> 0 | AN79: =AL79/$L79*$N79 -> 0 | AO79: 0 | AP79: =AO79/$L79*$M79 -> 0 | AQ79: =AO79/$L79*$N79 -> 0 | AR79: 30 | AS79: =AR79/$L79*$M79 -> 25.5 | AT79: =AR79/$L79*$N79 -> 4.5 | AU79: 30 | AV79: =AU79/$L79*$M79 -> 25.5 | AW79: =AU79/$L79*$N79 -> 4.5 | BA79: =$L79-$AI79 -> 45 | BB79: =$L79-$AL79 -> 45 | BC79: =$L79-$AO79 -> 45 | BD79: =$L79-$AR79 -> 15 | BE79: =$L79-$AU79 -> 15 | BF79: =$L79-$AX79 -> 45 | BG79: =BA79/$L79 -> 1 | BH79: =BB79/$L79 -> 1 | BI79: =BC79/$L79 -> 1 | BJ79: =BD79/$L79 -> 0.33333333 | BK79: =BE79/$L79 -> 0.33333333 | BL79: =BF79/$L79 -> 1 | BO79: DTC-RACK-R3-Z4E-R1-06 | BP79: =M79/0.9 -> 42.5 | BQ79: =IF($AI79>0, 1, 0) -> 0 | BR79: =IF($AL79>0, 1, 0) -> 0 | BS79: =IF($AO79>0, 1, 0) -> 0 | BT79: =IF($AR79>0, 1, 0) -> 1 | BU79: =IF($AU79>0, 1, 0) -> 1 | BV79: =IF(AX79>0, 1, 0) -> 0
A80: ZONE-R3-Z4E | B80: ROW-R3-Z4E-R1 | C80: 45 | F80: LL-R3-E | G80: AIRZONE-R3-E1 | H80: RACK-R3-Z4E-R1-07 | I80: POD-06 | J80: ="RACKPDU-"&H80&"-A" -> RACKPDU-RACK-R3-Z4E-R1-07-A | K80: ="RACKPDU-"&H80&"-B" -> RACKPDU-RACK-R3-Z4E-R1-07-B | L80: 45 | M80: =VLOOKUP($H80,'Cooling-Rack'!$A$2:$G$265,5,FALSE) -> 38.25 | N80: =VLOOKUP($H80,'Cooling-Rack'!$A$2:$G$265,7,FALSE) -> 6.75 | O80: 54 | P80: 0.85 | Q80: 0.15 | R80: RPP-R3-A3 | S80: RPP-R3-B4 | T80: RPDU-R3-A | U80: RPDU-R3R4-B | V80: UPS-02-A | W80: UPS-02-B | X80: BESS-01 | Y80: SWGR-01 | Z80: SWGR-02 | AA80: UTIL-01 | AB80: UTIL-02 | AC80: GEN-01 | AD80: GEN-02 | AE80: CC-R3 | AF80: BDL-R3 | AG80: BDL-RPDU-R3R4 | AH80: BDL-UPS-02 | AL80: 0 | AM80: =AL80/$L80*$M80 -> 0 | AN80: =AL80/$L80*$N80 -> 0 | AO80: 0 | AP80: =AO80/$L80*$M80 -> 0 | AQ80: =AO80/$L80*$N80 -> 0 | AR80: 30 | AS80: =AR80/$L80*$M80 -> 25.5 | AT80: =AR80/$L80*$N80 -> 4.5 | AU80: 30 | AV80: =AU80/$L80*$M80 -> 25.5 | AW80: =AU80/$L80*$N80 -> 4.5 | BA80: =$L80-$AI80 -> 45 | BB80: =$L80-$AL80 -> 45 | BC80: =$L80-$AO80 -> 45 | BD80: =$L80-$AR80 -> 15 | BE80: =$L80-$AU80 -> 15 | BF80: =$L80-$AX80 -> 45 | BG80: =BA80/$L80 -> 1 | BH80: =BB80/$L80 -> 1 | BI80: =BC80/$L80 -> 1 | BJ80: =BD80/$L80 -> 0.33333333 | BK80: =BE80/$L80 -> 0.33333333 | BL80: =BF80/$L80 -> 1 | BO80: DTC-RACK-R3-Z4E-R1-07 | BP80: =M80/0.9 -> 42.5 | BQ80: =IF($AI80>0, 1, 0) -> 0 | BR80: =IF($AL80>0, 1, 0) -> 0 | BS80: =IF($AO80>0, 1, 0) -> 0 | BT80: =IF($AR80>0, 1, 0) -> 1 | BU80: =IF($AU80>0, 1, 0) -> 1 | BV80: =IF(AX80>0, 1, 0) -> 0
A81: ZONE-R3-Z4E | B81: ROW-R3-Z4E-R1 | C81: 45 | F81: LL-R3-E | G81: AIRZONE-R3-E1 | H81: RACK-R3-Z4E-R1-08 | I81: POD-06 | J81: ="RACKPDU-"&H81&"-A" -> RACKPDU-RACK-R3-Z4E-R1-08-A | K81: ="RACKPDU-"&H81&"-B" -> RACKPDU-RACK-R3-Z4E-R1-08-B | L81: 45 | M81: =VLOOKUP($H81,'Cooling-Rack'!$A$2:$G$265,5,FALSE) -> 38.25 | N81: =VLOOKUP($H81,'Cooling-Rack'!$A$2:$G$265,7,FALSE) -> 6.75 | O81: 54 | P81: 0.85 | Q81: 0.15 | R81: RPP-R3-A3 | S81: RPP-R3-B4 | T81: RPDU-R3-A | U81: RPDU-R3R4-B | V81: UPS-02-A | W81: UPS-02-B | X81: BESS-01 | Y81: SWGR-01 | Z81: SWGR-02 | AA81: UTIL-01 | AB81: UTIL-02 | AC81: GEN-01 | AD81: GEN-02 | AE81: CC-R3 | AF81: BDL-R3 | AG81: BDL-RPDU-R3R4 | AH81: BDL-UPS-02 | AL81: 0 | AM81: =AL81/$L81*$M81 -> 0 | AN81: =AL81/$L81*$N81 -> 0 | AO81: 0 | AP81: =AO81/$L81*$M81 -> 0 | AQ81: =AO81/$L81*$N81 -> 0 | AR81: 30 | AS81: =AR81/$L81*$M81 -> 25.5 | AT81: =AR81/$L81*$N81 -> 4.5 | AU81: 30 | AV81: =AU81/$L81*$M81 -> 25.5 | AW81: =AU81/$L81*$N81 -> 4.5 | BA81: =$L81-$AI81 -> 45 | BB81: =$L81-$AL81 -> 45 | BC81: =$L81-$AO81 -> 45 | BD81: =$L81-$AR81 -> 15 | BE81: =$L81-$AU81 -> 15 | BF81: =$L81-$AX81 -> 45 | BG81: =BA81/$L81 -> 1 | BH81: =BB81/$L81 -> 1 | BI81: =BC81/$L81 -> 1 | BJ81: =BD81/$L81 -> 0.33333333 | BK81: =BE81/$L81 -> 0.33333333 | BL81: =BF81/$L81 -> 1 | BO81: DTC-RACK-R3-Z4E-R1-08 | BP81: =M81/0.9 -> 42.5 | BQ81: =IF($AI81>0, 1, 0) -> 0 | BR81: =IF($AL81>0, 1, 0) -> 0 | BS81: =IF($AO81>0, 1, 0) -> 0 | BT81: =IF($AR81>0, 1, 0) -> 1 | BU81: =IF($AU81>0, 1, 0) -> 1 | BV81: =IF(AX81>0, 1, 0) -> 0
A82: ZONE-R3-Z4E | B82: ROW-R3-Z4E-R1 | C82: 45 | F82: LL-R3-E | G82: AIRZONE-R3-E1 | H82: RACK-R3-Z4E-R1-09 | I82: POD-06 | J82: ="RACKPDU-"&H82&"-A" -> RACKPDU-RACK-R3-Z4E-R1-09-A | K82: ="RACKPDU-"&H82&"-B" -> RACKPDU-RACK-R3-Z4E-R1-09-B | L82: 45 | M82: =VLOOKUP($H82,'Cooling-Rack'!$A$2:$G$265,5,FALSE) -> 38.25 | N82: =VLOOKUP($H82,'Cooling-Rack'!$A$2:$G$265,7,FALSE) -> 6.75 | O82: 54 | P82: 0.85 | Q82: 0.15 | R82: RPP-R3-A3 | S82: RPP-R3-B4 | T82: RPDU-R3-A | U82: RPDU-R3R4-B | V82: UPS-02-A | W82: UPS-02-B | X82: BESS-01 | Y82: SWGR-01 | Z82: SWGR-02 | AA82: UTIL-01 | AB82: UTIL-02 | AC82: GEN-01 | AD82: GEN-02 | AE82: CC-R3 | AF82: BDL-R3 | AG82: BDL-RPDU-R3R4 | AH82: BDL-UPS-02 | AL82: 0 | AM82: =AL82/$L82*$M82 -> 0 | AN82: =AL82/$L82*$N82 -> 0 | AO82: 0 | AP82: =AO82/$L82*$M82 -> 0 | AQ82: =AO82/$L82*$N82 -> 0 | AR82: 30 | AS82: =AR82/$L82*$M82 -> 25.5 | AT82: =AR82/$L82*$N82 -> 4.5 | AU82: 30 | AV82: =AU82/$L82*$M82 -> 25.5 | AW82: =AU82/$L82*$N82 -> 4.5 | BA82: =$L82-$AI82 -> 45 | BB82: =$L82-$AL82 -> 45 | BC82: =$L82-$AO82 -> 45 | BD82: =$L82-$AR82 -> 15 | BE82: =$L82-$AU82 -> 15 | BF82: =$L82-$AX82 -> 45 | BG82: =BA82/$L82 -> 1 | BH82: =BB82/$L82 -> 1 | BI82: =BC82/$L82 -> 1 | BJ82: =BD82/$L82 -> 0.33333333 | BK82: =BE82/$L82 -> 0.33333333 | BL82: =BF82/$L82 -> 1 | BO82: DTC-RACK-R3-Z4E-R1-09 | BP82: =M82/0.9 -> 42.5 | BQ82: =IF($AI82>0, 1, 0) -> 0 | BR82: =IF($AL82>0, 1, 0) -> 0 | BS82: =IF($AO82>0, 1, 0) -> 0 | BT82: =IF($AR82>0, 1, 0) -> 1 | BU82: =IF($AU82>0, 1, 0) -> 1 | BV82: =IF(AX82>0, 1, 0) -> 0
A83: ZONE-R3-Z4E | B83: ROW-R3-Z4E-R1 | C83: 45 | F83: LL-R3-E | G83: AIRZONE-R3-E1 | H83: RACK-R3-Z4E-R1-10 | I83: POD-06 | J83: ="RACKPDU-"&H83&"-A" -> RACKPDU-RACK-R3-Z4E-R1-10-A | K83: ="RACKPDU-"&H83&"-B" -> RACKPDU-RACK-R3-Z4E-R1-10-B | L83: 45 | M83: =VLOOKUP($H83,'Cooling-Rack'!$A$2:$G$265,5,FALSE) -> 38.25 | N83: =VLOOKUP($H83,'Cooling-Rack'!$A$2:$G$265,7,FALSE) -> 6.75 | O83: 54 | P83: 0.85 | Q83: 0.15 | R83: RPP-R3-A3 | S83: RPP-R3-B4 | T83: RPDU-R3-A | U83: RPDU-R3R4-B | V83: UPS-02-A | W83: UPS-02-B | X83: BESS-01 | Y83: SWGR-01 | Z83: SWGR-02 | AA83: UTIL-01 | AB83: UTIL-02 | AC83: GEN-01 | AD83: GEN-02 | AE83: CC-R3 | AF83: BDL-R3 | AG83: BDL-RPDU-R3R4 | AH83: BDL-UPS-02 | AL83: 0 | AM83: =AL83/$L83*$M83 -> 0 | AN83: =AL83/$L83*$N83 -> 0 | AO83: 0 | AP83: =AO83/$L83*$M83 -> 0 | AQ83: =AO83/$L83*$N83 -> 0 | AR83: 30 | AS83: =AR83/$L83*$M83 -> 25.5 | AT83: =AR83/$L83*$N83 -> 4.5 | AU83: 30 | AV83: =AU83/$L83*$M83 -> 25.5 | AW83: =AU83/$L83*$N83 -> 4.5 | BA83: =$L83-$AI83 -> 45 | BB83: =$L83-$AL83 -> 45 | BC83: =$L83-$AO83 -> 45 | BD83: =$L83-$AR83 -> 15 | BE83: =$L83-$AU83 -> 15 | BF83: =$L83-$AX83 -> 45 | BG83: =BA83/$L83 -> 1 | BH83: =BB83/$L83 -> 1 | BI83: =BC83/$L83 -> 1 | BJ83: =BD83/$L83 -> 0.33333333 | BK83: =BE83/$L83 -> 0.33333333 | BL83: =BF83/$L83 -> 1 | BO83: DTC-RACK-R3-Z4E-R1-10 | BP83: =M83/0.9 -> 42.5 | BQ83: =IF($AI83>0, 1, 0) -> 0 | BR83: =IF($AL83>0, 1, 0) -> 0 | BS83: =IF($AO83>0, 1, 0) -> 0 | BT83: =IF($AR83>0, 1, 0) -> 1 | BU83: =IF($AU83>0, 1, 0) -> 1 | BV83: =IF(AX83>0, 1, 0) -> 0
A84: ZONE-R3-Z4E | B84: ROW-R3-Z4E-R1 | C84: 45 | F84: LL-R3-E | G84: AIRZONE-R3-E1 | H84: RACK-R3-Z4E-R1-11 | I84: POD-06 | J84: ="RACKPDU-"&H84&"-A" -> RACKPDU-RACK-R3-Z4E-R1-11-A | K84: ="RACKPDU-"&H84&"-B" -> RACKPDU-RACK-R3-Z4E-R1-11-B | L84: 45 | M84: =VLOOKUP($H84,'Cooling-Rack'!$A$2:$G$265,5,FALSE) -> 38.25 | N84: =VLOOKUP($H84,'Cooling-Rack'!$A$2:$G$265,7,FALSE) -> 6.75 | O84: 54 | P84: 0.85 | Q84: 0.15 | R84: RPP-R3-A3 | S84: RPP-R3-B4 | T84: RPDU-R3-A | U84: RPDU-R3R4-B | V84: UPS-02-A | W84: UPS-02-B | X84: BESS-01 | Y84: SWGR-01 | Z84: SWGR-02 | AA84: UTIL-01 | AB84: UTIL-02 | AC84: GEN-01 | AD84: GEN-02 | AE84: CC-R3 | AF84: BDL-R3 | AG84: BDL-RPDU-R3R4 | AH84: BDL-UPS-02 | AL84: 0 | AM84: =AL84/$L84*$M84 -> 0 | AN84: =AL84/$L84*$N84 -> 0 | AO84: 0 | AP84: =AO84/$L84*$M84 -> 0 | AQ84: =AO84/$L84*$N84 -> 0 | AR84: 30 | AS84: =AR84/$L84*$M84 -> 25.5 | AT84: =AR84/$L84*$N84 -> 4.5 | AU84: 30 | AV84: =AU84/$L84*$M84 -> 25.5 | AW84: =AU84/$L84*$N84 -> 4.5 | BA84: =$L84-$AI84 -> 45 | BB84: =$L84-$AL84 -> 45 | BC84: =$L84-$AO84 -> 45 | BD84: =$L84-$AR84 -> 15 | BE84: =$L84-$AU84 -> 15 | BF84: =$L84-$AX84 -> 45 | BG84: =BA84/$L84 -> 1 | BH84: =BB84/$L84 -> 1 | BI84: =BC84/$L84 -> 1 | BJ84: =BD84/$L84 -> 0.33333333 | BK84: =BE84/$L84 -> 0.33333333 | BL84: =BF84/$L84 -> 1 | BO84: DTC-RACK-R3-Z4E-R1-11 | BP84: =M84/0.9 -> 42.5 | BQ84: =IF($AI84>0, 1, 0) -> 0 | BR84: =IF($AL84>0, 1, 0) -> 0 | BS84: =IF($AO84>0, 1, 0) -> 0 | BT84: =IF($AR84>0, 1, 0) -> 1 | BU84: =IF($AU84>0, 1, 0) -> 1 | BV84: =IF(AX84>0, 1, 0) -> 0
A85: ZONE-R3-Z4E | B85: ROW-R3-Z4E-R1 | C85: 45 | F85: LL-R3-E | G85: AIRZONE-R3-E1 | H85: RACK-R3-Z4E-R1-12 | I85: POD-06 | J85: ="RACKPDU-"&H85&"-A" -> RACKPDU-RACK-R3-Z4E-R1-12-A | K85: ="RACKPDU-"&H85&"-B" -> RACKPDU-RACK-R3-Z4E-R1-12-B | L85: 45 | M85: =VLOOKUP($H85,'Cooling-Rack'!$A$2:$G$265,5,FALSE) -> 38.25 | N85: =VLOOKUP($H85,'Cooling-Rack'!$A$2:$G$265,7,FALSE) -> 6.75 | O85: 54 | P85: 0.85 | Q85: 0.15 | R85: RPP-R3-A3 | S85: RPP-R3-B4 | T85: RPDU-R3-A | U85: RPDU-R3R4-B | V85: UPS-02-A | W85: UPS-02-B | X85: BESS-01 | Y85: SWGR-01 | Z85: SWGR-02 | AA85: UTIL-01 | AB85: UTIL-02 | AC85: GEN-01 | AD85: GEN-02 | AE85: CC-R3 | AF85: BDL-R3 | AG85: BDL-RPDU-R3R4 | AH85: BDL-UPS-02 | AL85: 0 | AM85: =AL85/$L85*$M85 -> 0 | AN85: =AL85/$L85*$N85 -> 0 | AO85: 0 | AP85: =AO85/$L85*$M85 -> 0 | AQ85: =AO85/$L85*$N85 -> 0 | AR85: 30 | AS85: =AR85/$L85*$M85 -> 25.5 | AT85: =AR85/$L85*$N85 -> 4.5 | AU85: 30 | AV85: =AU85/$L85*$M85 -> 25.5 | AW85: =AU85/$L85*$N85 -> 4.5 | BA85: =$L85-$AI85 -> 45 | BB85: =$L85-$AL85 -> 45 | BC85: =$L85-$AO85 -> 45 | BD85: =$L85-$AR85 -> 15 | BE85: =$L85-$AU85 -> 15 | BF85: =$L85-$AX85 -> 45 | BG85: =BA85/$L85 -> 1 | BH85: =BB85/$L85 -> 1 | BI85: =BC85/$L85 -> 1 | BJ85: =BD85/$L85 -> 0.33333333 | BK85: =BE85/$L85 -> 0.33333333 | BL85: =BF85/$L85 -> 1 | BO85: DTC-RACK-R3-Z4E-R1-12 | BP85: =M85/0.9 -> 42.5 | BQ85: =IF($AI85>0, 1, 0) -> 0 | BR85: =IF($AL85>0, 1, 0) -> 0 | BS85: =IF($AO85>0, 1, 0) -> 0 | BT85: =IF($AR85>0, 1, 0) -> 1 | BU85: =IF($AU85>0, 1, 0) -> 1 | BV85: =IF(AX85>0, 1, 0) -> 0
A86: ZONE-R3-Z4E | B86: ROW-R3-Z4E-R2 | C86: 45 | F86: LL-R3-E | G86: AIRZONE-R3-E1 | H86: RACK-R3-Z4E-R2-01 | I86: POD-06 | J86: ="RACKPDU-"&H86&"-A" -> RACKPDU-RACK-R3-Z4E-R2-01-A | K86: ="RACKPDU-"&H86&"-B" -> RACKPDU-RACK-R3-Z4E-R2-01-B | L86: 45 | M86: =VLOOKUP($H86,'Cooling-Rack'!$A$2:$G$265,5,FALSE) -> 38.25 | N86: =VLOOKUP($H86,'Cooling-Rack'!$A$2:$G$265,7,FALSE) -> 6.75 | O86: 54 | P86: 0.85 | Q86: 0.15 | R86: RPP-R3-A2 | S86: RPP-R3-B2 | T86: RPDU-R3-A | U86: RPDU-R3R4-B | V86: UPS-02-A | W86: UPS-02-B | X86: BESS-01 | Y86: SWGR-01 | Z86: SWGR-02 | AA86: UTIL-01 | AB86: UTIL-02 | AC86: GEN-01 | AD86: GEN-02 | AE86: CC-R3 | AF86: BDL-R3 | AG86: BDL-RPDU-R3R4 | AH86: BDL-UPS-02 | AL86: 0 | AM86: =AL86/$L86*$M86 -> 0 | AN86: =AL86/$L86*$N86 -> 0 | AO86: 0 | AP86: =AO86/$L86*$M86 -> 0 | AQ86: =AO86/$L86*$N86 -> 0 | AS86: =AR86/$L86*$M86 -> 0 | AT86: =AR86/$L86*$N86 -> 0 | AU86: 30 | AV86: =AU86/$L86*$M86 -> 25.5 | AW86: =AU86/$L86*$N86 -> 4.5 | BA86: =$L86-$AI86 -> 45 | BB86: =$L86-$AL86 -> 45 | BC86: =$L86-$AO86 -> 45 | BD86: =$L86-$AR86 -> 45 | BE86: =$L86-$AU86 -> 15 | BF86: =$L86-$AX86 -> 45 | BG86: =BA86/$L86 -> 1 | BH86: =BB86/$L86 -> 1 | BI86: =BC86/$L86 -> 1 | BJ86: =BD86/$L86 -> 1 | BK86: =BE86/$L86 -> 0.33333333 | BL86: =BF86/$L86 -> 1 | BO86: DTC-RACK-R3-Z4E-R2-01 | BP86: =M86/0.9 -> 42.5 | BQ86: =IF($AI86>0, 1, 0) -> 0 | BR86: =IF($AL86>0, 1, 0) -> 0 | BS86: =IF($AO86>0, 1, 0) -> 0 | BT86: =IF($AR86>0, 1, 0) -> 0 | BU86: =IF($AU86>0, 1, 0) -> 1 | BV86: =IF(AX86>0, 1, 0) -> 0
A87: ZONE-R3-Z4E | B87: ROW-R3-Z4E-R2 | C87: 45 | F87: LL-R3-E | G87: AIRZONE-R3-E1 | H87: RACK-R3-Z4E-R2-02 | I87: POD-06 | J87: ="RACKPDU-"&H87&"-A" -> RACKPDU-RACK-R3-Z4E-R2-02-A | K87: ="RACKPDU-"&H87&"-B" -> RACKPDU-RACK-R3-Z4E-R2-02-B | L87: 45 | M87: =VLOOKUP($H87,'Cooling-Rack'!$A$2:$G$265,5,FALSE) -> 38.25 | N87: =VLOOKUP($H87,'Cooling-Rack'!$A$2:$G$265,7,FALSE) -> 6.75 | O87: 54 | P87: 0.85 | Q87: 0.15 | R87: RPP-R3-A2 | S87: RPP-R3-B2 | T87: RPDU-R3-A | U87: RPDU-R3R4-B | V87: UPS-02-A | W87: UPS-02-B | X87: BESS-01 | Y87: SWGR-01 | Z87: SWGR-02 | AA87: UTIL-01 | AB87: UTIL-02 | AC87: GEN-01 | AD87: GEN-02 | AE87: CC-R3 | AF87: BDL-R3 | AG87: BDL-RPDU-R3R4 | AH87: BDL-UPS-02 | AL87: 0 | AM87: =AL87/$L87*$M87 -> 0 | AN87: =AL87/$L87*$N87 -> 0 | AO87: 0 | AP87: =AO87/$L87*$M87 -> 0 | AQ87: =AO87/$L87*$N87 -> 0 | AS87: =AR87/$L87*$M87 -> 0 | AT87: =AR87/$L87*$N87 -> 0 | AU87: 30 | AV87: =AU87/$L87*$M87 -> 25.5 | AW87: =AU87/$L87*$N87 -> 4.5 | BA87: =$L87-$AI87 -> 45 | BB87: =$L87-$AL87 -> 45 | BC87: =$L87-$AO87 -> 45 | BD87: =$L87-$AR87 -> 45 | BE87: =$L87-$AU87 -> 15 | BF87: =$L87-$AX87 -> 45 | BG87: =BA87/$L87 -> 1 | BH87: =BB87/$L87 -> 1 | BI87: =BC87/$L87 -> 1 | BJ87: =BD87/$L87 -> 1 | BK87: =BE87/$L87 -> 0.33333333 | BL87: =BF87/$L87 -> 1 | BO87: DTC-RACK-R3-Z4E-R2-02 | BP87: =M87/0.9 -> 42.5 | BQ87: =IF($AI87>0, 1, 0) -> 0 | BR87: =IF($AL87>0, 1, 0) -> 0 | BS87: =IF($AO87>0, 1, 0) -> 0 | BT87: =IF($AR87>0, 1, 0) -> 0 | BU87: =IF($AU87>0, 1, 0) -> 1 | BV87: =IF(AX87>0, 1, 0) -> 0
A88: ZONE-R3-Z4E | B88: ROW-R3-Z4E-R2 | C88: 45 | F88: LL-R3-E | G88: AIRZONE-R3-E1 | H88: RACK-R3-Z4E-R2-03 | I88: POD-06 | J88: ="RACKPDU-"&H88&"-A" -> RACKPDU-RACK-R3-Z4E-R2-03-A | K88: ="RACKPDU-"&H88&"-B" -> RACKPDU-RACK-R3-Z4E-R2-03-B | L88: 45 | M88: =VLOOKUP($H88,'Cooling-Rack'!$A$2:$G$265,5,FALSE) -> 38.25 | N88: =VLOOKUP($H88,'Cooling-Rack'!$A$2:$G$265,7,FALSE) -> 6.75 | O88: 54 | P88: 0.85 | Q88: 0.15 | R88: RPP-R3-A2 | S88: RPP-R3-B2 | T88: RPDU-R3-A | U88: RPDU-R3R4-B | V88: UPS-02-A | W88: UPS-02-B | X88: BESS-01 | Y88: SWGR-01 | Z88: SWGR-02 | AA88: UTIL-01 | AB88: UTIL-02 | AC88: GEN-01 | AD88: GEN-02 | AE88: CC-R3 | AF88: BDL-R3 | AG88: BDL-RPDU-R3R4 | AH88: BDL-UPS-02 | AL88: 0 | AM88: =AL88/$L88*$M88 -> 0 | AN88: =AL88/$L88*$N88 -> 0 | AO88: 0 | AP88: =AO88/$L88*$M88 -> 0 | AQ88: =AO88/$L88*$N88 -> 0 | AS88: =AR88/$L88*$M88 -> 0 | AT88: =AR88/$L88*$N88 -> 0 | AU88: 30 | AV88: =AU88/$L88*$M88 -> 25.5 | AW88: =AU88/$L88*$N88 -> 4.5 | BA88: =$L88-$AI88 -> 45 | BB88: =$L88-$AL88 -> 45 | BC88: =$L88-$AO88 -> 45 | BD88: =$L88-$AR88 -> 45 | BE88: =$L88-$AU88 -> 15 | BF88: =$L88-$AX88 -> 45 | BG88: =BA88/$L88 -> 1 | BH88: =BB88/$L88 -> 1 | BI88: =BC88/$L88 -> 1 | BJ88: =BD88/$L88 -> 1 | BK88: =BE88/$L88 -> 0.33333333 | BL88: =BF88/$L88 -> 1 | BO88: DTC-RACK-R3-Z4E-R2-03 | BP88: =M88/0.9 -> 42.5 | BQ88: =IF($AI88>0, 1, 0) -> 0 | BR88: =IF($AL88>0, 1, 0) -> 0 | BS88: =IF($AO88>0, 1, 0) -> 0 | BT88: =IF($AR88>0, 1, 0) -> 0 | BU88: =IF($AU88>0, 1, 0) -> 1 | BV88: =IF(AX88>0, 1, 0) -> 0
A89: ZONE-R3-Z4E | B89: ROW-R3-Z4E-R2 | C89: 45 | F89: LL-R3-E | G89: AIRZONE-R3-E1 | H89: RACK-R3-Z4E-R2-04 | I89: POD-06 | J89: ="RACKPDU-"&H89&"-A" -> RACKPDU-RACK-R3-Z4E-R2-04-A | K89: ="RACKPDU-"&H89&"-B" -> RACKPDU-RACK-R3-Z4E-R2-04-B | L89: 45 | M89: =VLOOKUP($H89,'Cooling-Rack'!$A$2:$G$265,5,FALSE) -> 38.25 | N89: =VLOOKUP($H89,'Cooling-Rack'!$A$2:$G$265,7,FALSE) -> 6.75 | O89: 54 | P89: 0.85 | Q89: 0.15 | R89: RPP-R3-A2 | S89: RPP-R3-B2 | T89: RPDU-R3-A | U89: RPDU-R3R4-B | V89: UPS-02-A | W89: UPS-02-B | X89: BESS-01 | Y89: SWGR-01 | Z89: SWGR-02 | AA89: UTIL-01 | AB89: UTIL-02 | AC89: GEN-01 | AD89: GEN-02 | AE89: CC-R3 | AF89: BDL-R3 | AG89: BDL-RPDU-R3R4 | AH89: BDL-UPS-02 | AL89: 0 | AM89: =AL89/$L89*$M89 -> 0 | AN89: =AL89/$L89*$N89 -> 0 | AO89: 0 | AP89: =AO89/$L89*$M89 -> 0 | AQ89: =AO89/$L89*$N89 -> 0 | AS89: =AR89/$L89*$M89 -> 0 | AT89: =AR89/$L89*$N89 -> 0 | AU89: 30 | AV89: =AU89/$L89*$M89 -> 25.5 | AW89: =AU89/$L89*$N89 -> 4.5 | BA89: =$L89-$AI89 -> 45 | BB89: =$L89-$AL89 -> 45 | BC89: =$L89-$AO89 -> 45 | BD89: =$L89-$AR89 -> 45 | BE89: =$L89-$AU89 -> 15 | BF89: =$L89-$AX89 -> 45 | BG89: =BA89/$L89 -> 1 | BH89: =BB89/$L89 -> 1 | BI89: =BC89/$L89 -> 1 | BJ89: =BD89/$L89 -> 1 | BK89: =BE89/$L89 -> 0.33333333 | BL89: =BF89/$L89 -> 1 | BO89: DTC-RACK-R3-Z4E-R2-04 | BP89: =M89/0.9 -> 42.5 | BQ89: =IF($AI89>0, 1, 0) -> 0 | BR89: =IF($AL89>0, 1, 0) -> 0 | BS89: =IF($AO89>0, 1, 0) -> 0 | BT89: =IF($AR89>0, 1, 0) -> 0 | BU89: =IF($AU89>0, 1, 0) -> 1 | BV89: =IF(AX89>0, 1, 0) -> 0
A90: ZONE-R3-Z4E | B90: ROW-R3-Z4E-R2 | C90: 45 | F90: LL-R3-E | G90: AIRZONE-R3-E1 | H90: RACK-R3-Z4E-R2-05 | I90: POD-06 | J90: ="RACKPDU-"&H90&"-A" -> RACKPDU-RACK-R3-Z4E-R2-05-A | K90: ="RACKPDU-"&H90&"-B" -> RACKPDU-RACK-R3-Z4E-R2-05-B | L90: 45 | M90: =VLOOKUP($H90,'Cooling-Rack'!$A$2:$G$265,5,FALSE) -> 38.25 | N90: =VLOOKUP($H90,'Cooling-Rack'!$A$2:$G$265,7,FALSE) -> 6.75 | O90: 54 | P90: 0.85 | Q90: 0.15 | R90: RPP-R3-A4 | S90: RPP-R3-B2 | T90: RPDU-R3-A | U90: RPDU-R3R4-B | V90: UPS-02-A | W90: UPS-02-B | X90: BESS-01 | Y90: SWGR-01 | Z90: SWGR-02 | AA90: UTIL-01 | AB90: UTIL-02 | AC90: GEN-01 | AD90: GEN-02 | AE90: CC-R3 | AF90: BDL-R3 | AG90: BDL-RPDU-R3R4 | AH90: BDL-UPS-02 | AL90: 0 | AM90: =AL90/$L90*$M90 -> 0 | AN90: =AL90/$L90*$N90 -> 0 | AO90: 0 | AP90: =AO90/$L90*$M90 -> 0 | AQ90: =AO90/$L90*$N90 -> 0 | AR90: 30 | AS90: =AR90/$L90*$M90 -> 25.5 | AT90: =AR90/$L90*$N90 -> 4.5 | AU90: 30 | AV90: =AU90/$L90*$M90 -> 25.5 | AW90: =AU90/$L90*$N90 -> 4.5 | BA90: =$L90-$AI90 -> 45 | BB90: =$L90-$AL90 -> 45 | BC90: =$L90-$AO90 -> 45 | BD90: =$L90-$AR90 -> 15 | BE90: =$L90-$AU90 -> 15 | BF90: =$L90-$AX90 -> 45 | BG90: =BA90/$L90 -> 1 | BH90: =BB90/$L90 -> 1 | BI90: =BC90/$L90 -> 1 | BJ90: =BD90/$L90 -> 0.33333333 | BK90: =BE90/$L90 -> 0.33333333 | BL90: =BF90/$L90 -> 1 | BO90: DTC-RACK-R3-Z4E-R2-05 | BP90: =M90/0.9 -> 42.5 | BQ90: =IF($AI90>0, 1, 0) -> 0 | BR90: =IF($AL90>0, 1, 0) -> 0 | BS90: =IF($AO90>0, 1, 0) -> 0 | BT90: =IF($AR90>0, 1, 0) -> 1 | BU90: =IF($AU90>0, 1, 0) -> 1 | BV90: =IF(AX90>0, 1, 0) -> 0
A91: ZONE-R3-Z4E | B91: ROW-R3-Z4E-R2 | C91: 45 | F91: LL-R3-E | G91: AIRZONE-R3-E1 | H91: RACK-R3-Z4E-R2-06 | I91: POD-06 | J91: ="RACKPDU-"&H91&"-A" -> RACKPDU-RACK-R3-Z4E-R2-06-A | K91: ="RACKPDU-"&H91&"-B" -> RACKPDU-RACK-R3-Z4E-R2-06-B | L91: 45 | M91: =VLOOKUP($H91,'Cooling-Rack'!$A$2:$G$265,5,FALSE) -> 38.25 | N91: =VLOOKUP($H91,'Cooling-Rack'!$A$2:$G$265,7,FALSE) -> 6.75 | O91: 54 | P91: 0.85 | Q91: 0.15 | R91: RPP-R3-A4 | S91: RPP-R3-B2 | T91: RPDU-R3-A | U91: RPDU-R3R4-B | V91: UPS-02-A | W91: UPS-02-B | X91: BESS-01 | Y91: SWGR-01 | Z91: SWGR-02 | AA91: UTIL-01 | AB91: UTIL-02 | AC91: GEN-01 | AD91: GEN-02 | AE91: CC-R3 | AF91: BDL-R3 | AG91: BDL-RPDU-R3R4 | AH91: BDL-UPS-02 | AL91: 0 | AM91: =AL91/$L91*$M91 -> 0 | AN91: =AL91/$L91*$N91 -> 0 | AO91: 0 | AP91: =AO91/$L91*$M91 -> 0 | AQ91: =AO91/$L91*$N91 -> 0 | AR91: 30 | AS91: =AR91/$L91*$M91 -> 25.5 | AT91: =AR91/$L91*$N91 -> 4.5 | AU91: 30 | AV91: =AU91/$L91*$M91 -> 25.5 | AW91: =AU91/$L91*$N91 -> 4.5 | BA91: =$L91-$AI91 -> 45 | BB91: =$L91-$AL91 -> 45 | BC91: =$L91-$AO91 -> 45 | BD91: =$L91-$AR91 -> 15 | BE91: =$L91-$AU91 -> 15 | BF91: =$L91-$AX91 -> 45 | BG91: =BA91/$L91 -> 1 | BH91: =BB91/$L91 -> 1 | BI91: =BC91/$L91 -> 1 | BJ91: =BD91/$L91 -> 0.33333333 | BK91: =BE91/$L91 -> 0.33333333 | BL91: =BF91/$L91 -> 1 | BO91: DTC-RACK-R3-Z4E-R2-06 | BP91: =M91/0.9 -> 42.5 | BQ91: =IF($AI91>0, 1, 0) -> 0 | BR91: =IF($AL91>0, 1, 0) -> 0 | BS91: =IF($AO91>0, 1, 0) -> 0 | BT91: =IF($AR91>0, 1, 0) -> 1 | BU91: =IF($AU91>0, 1, 0) -> 1 | BV91: =IF(AX91>0, 1, 0) -> 0
A92: ZONE-R3-Z4E | B92: ROW-R3-Z4E-R2 | C92: 45 | F92: LL-R3-E | G92: AIRZONE-R3-E1 | H92: RACK-R3-Z4E-R2-07 | I92: POD-06 | J92: ="RACKPDU-"&H92&"-A" -> RACKPDU-RACK-R3-Z4E-R2-07-A | K92: ="RACKPDU-"&H92&"-B" -> RACKPDU-RACK-R3-Z4E-R2-07-B | L92: 45 | M92: =VLOOKUP($H92,'Cooling-Rack'!$A$2:$G$265,5,FALSE) -> 38.25 | N92: =VLOOKUP($H92,'Cooling-Rack'!$A$2:$G$265,7,FALSE) -> 6.75 | O92: 54 | P92: 0.85 | Q92: 0.15 | R92: RPP-R3-A4 | S92: RPP-R3-B4 | T92: RPDU-R3-A | U92: RPDU-R3R4-B | V92: UPS-02-A | W92: UPS-02-B | X92: BESS-01 | Y92: SWGR-01 | Z92: SWGR-02 | AA92: UTIL-01 | AB92: UTIL-02 | AC92: GEN-01 | AD92: GEN-02 | AE92: CC-R3 | AF92: BDL-R3 | AG92: BDL-RPDU-R3R4 | AH92: BDL-UPS-02 | AL92: 0 | AM92: =AL92/$L92*$M92 -> 0 | AN92: =AL92/$L92*$N92 -> 0 | AO92: 0 | AP92: =AO92/$L92*$M92 -> 0 | AQ92: =AO92/$L92*$N92 -> 0 | AR92: 30 | AS92: =AR92/$L92*$M92 -> 25.5 | AT92: =AR92/$L92*$N92 -> 4.5 | AU92: 30 | AV92: =AU92/$L92*$M92 -> 25.5 | AW92: =AU92/$L92*$N92 -> 4.5 | BA92: =$L92-$AI92 -> 45 | BB92: =$L92-$AL92 -> 45 | BC92: =$L92-$AO92 -> 45 | BD92: =$L92-$AR92 -> 15 | BE92: =$L92-$AU92 -> 15 | BF92: =$L92-$AX92 -> 45 | BG92: =BA92/$L92 -> 1 | BH92: =BB92/$L92 -> 1 | BI92: =BC92/$L92 -> 1 | BJ92: =BD92/$L92 -> 0.33333333 | BK92: =BE92/$L92 -> 0.33333333 | BL92: =BF92/$L92 -> 1 | BO92: DTC-RACK-R3-Z4E-R2-07 | BP92: =M92/0.9 -> 42.5 | BQ92: =IF($AI92>0, 1, 0) -> 0 | BR92: =IF($AL92>0, 1, 0) -> 0 | BS92: =IF($AO92>0, 1, 0) -> 0 | BT92: =IF($AR92>0, 1, 0) -> 1 | BU92: =IF($AU92>0, 1, 0) -> 1 | BV92: =IF(AX92>0, 1, 0) -> 0
A93: ZONE-R3-Z4E | B93: ROW-R3-Z4E-R2 | C93: 45 | F93: LL-R3-E | G93: AIRZONE-R3-E1 | H93: RACK-R3-Z4E-R2-08 | I93: POD-06 | J93: ="RACKPDU-"&H93&"-A" -> RACKPDU-RACK-R3-Z4E-R2-08-A | K93: ="RACKPDU-"&H93&"-B" -> RACKPDU-RACK-R3-Z4E-R2-08-B | L93: 45 | M93: =VLOOKUP($H93,'Cooling-Rack'!$A$2:$G$265,5,FALSE) -> 38.25 | N93: =VLOOKUP($H93,'Cooling-Rack'!$A$2:$G$265,7,FALSE) -> 6.75 | O93: 54 | P93: 0.85 | Q93: 0.15 | R93: RPP-R3-A4 | S93: RPP-R3-B4 | T93: RPDU-R3-A | U93: RPDU-R3R4-B | V93: UPS-02-A | W93: UPS-02-B | X93: BESS-01 | Y93: SWGR-01 | Z93: SWGR-02 | AA93: UTIL-01 | AB93: UTIL-02 | AC93: GEN-01 | AD93: GEN-02 | AE93: CC-R3 | AF93: BDL-R3 | AG93: BDL-RPDU-R3R4 | AH93: BDL-UPS-02 | AL93: 0 | AM93: =AL93/$L93*$M93 -> 0 | AN93: =AL93/$L93*$N93 -> 0 | AO93: 0 | AP93: =AO93/$L93*$M93 -> 0 | AQ93: =AO93/$L93*$N93 -> 0 | AR93: 30 | AS93: =AR93/$L93*$M93 -> 25.5 | AT93: =AR93/$L93*$N93 -> 4.5 | AU93: 30 | AV93: =AU93/$L93*$M93 -> 25.5 | AW93: =AU93/$L93*$N93 -> 4.5 | BA93: =$L93-$AI93 -> 45 | BB93: =$L93-$AL93 -> 45 | BC93: =$L93-$AO93 -> 45 | BD93: =$L93-$AR93 -> 15 | BE93: =$L93-$AU93 -> 15 | BF93: =$L93-$AX93 -> 45 | BG93: =BA93/$L93 -> 1 | BH93: =BB93/$L93 -> 1 | BI93: =BC93/$L93 -> 1 | BJ93: =BD93/$L93 -> 0.33333333 | BK93: =BE93/$L93 -> 0.33333333 | BL93: =BF93/$L93 -> 1 | BO93: DTC-RACK-R3-Z4E-R2-08 | BP93: =M93/0.9 -> 42.5 | BQ93: =IF($AI93>0, 1, 0) -> 0 | BR93: =IF($AL93>0, 1, 0) -> 0 | BS93: =IF($AO93>0, 1, 0) -> 0 | BT93: =IF($AR93>0, 1, 0) -> 1 | BU93: =IF($AU93>0, 1, 0) -> 1 | BV93: =IF(AX93>0, 1, 0) -> 0
A94: ZONE-R3-Z4E | B94: ROW-R3-Z4E-R2 | C94: 45 | F94: LL-R3-E | G94: AIRZONE-R3-E1 | H94: RACK-R3-Z4E-R2-09 | I94: POD-06 | J94: ="RACKPDU-"&H94&"-A" -> RACKPDU-RACK-R3-Z4E-R2-09-A | K94: ="RACKPDU-"&H94&"-B" -> RACKPDU-RACK-R3-Z4E-R2-09-B | L94: 45 | M94: =VLOOKUP($H94,'Cooling-Rack'!$A$2:$G$265,5,FALSE) -> 38.25 | N94: =VLOOKUP($H94,'Cooling-Rack'!$A$2:$G$265,7,FALSE) -> 6.75 | O94: 54 | P94: 0.85 | Q94: 0.15 | R94: RPP-R3-A4 | S94: RPP-R3-B4 | T94: RPDU-R3-A | U94: RPDU-R3R4-B | V94: UPS-02-A | W94: UPS-02-B | X94: BESS-01 | Y94: SWGR-01 | Z94: SWGR-02 | AA94: UTIL-01 | AB94: UTIL-02 | AC94: GEN-01 | AD94: GEN-02 | AE94: CC-R3 | AF94: BDL-R3 | AG94: BDL-RPDU-R3R4 | AH94: BDL-UPS-02 | AL94: 0 | AM94: =AL94/$L94*$M94 -> 0 | AN94: =AL94/$L94*$N94 -> 0 | AO94: 0 | AP94: =AO94/$L94*$M94 -> 0 | AQ94: =AO94/$L94*$N94 -> 0 | AR94: 30 | AS94: =AR94/$L94*$M94 -> 25.5 | AT94: =AR94/$L94*$N94 -> 4.5 | AU94: 30 | AV94: =AU94/$L94*$M94 -> 25.5 | AW94: =AU94/$L94*$N94 -> 4.5 | BA94: =$L94-$AI94 -> 45 | BB94: =$L94-$AL94 -> 45 | BC94: =$L94-$AO94 -> 45 | BD94: =$L94-$AR94 -> 15 | BE94: =$L94-$AU94 -> 15 | BF94: =$L94-$AX94 -> 45 | BG94: =BA94/$L94 -> 1 | BH94: =BB94/$L94 -> 1 | BI94: =BC94/$L94 -> 1 | BJ94: =BD94/$L94 -> 0.33333333 | BK94: =BE94/$L94 -> 0.33333333 | BL94: =BF94/$L94 -> 1 | BO94: DTC-RACK-R3-Z4E-R2-09 | BP94: =M94/0.9 -> 42.5 | BQ94: =IF($AI94>0, 1, 0) -> 0 | BR94: =IF($AL94>0, 1, 0) -> 0 | BS94: =IF($AO94>0, 1, 0) -> 0 | BT94: =IF($AR94>0, 1, 0) -> 1 | BU94: =IF($AU94>0, 1, 0) -> 1 | BV94: =IF(AX94>0, 1, 0) -> 0
A95: ZONE-R3-Z4E | B95: ROW-R3-Z4E-R2 | C95: 45 | F95: LL-R3-E | G95: AIRZONE-R3-E1 | H95: RACK-R3-Z4E-R2-10 | I95: POD-06 | J95: ="RACKPDU-"&H95&"-A" -> RACKPDU-RACK-R3-Z4E-R2-10-A | K95: ="RACKPDU-"&H95&"-B" -> RACKPDU-RACK-R3-Z4E-R2-10-B | L95: 45 | M95: =VLOOKUP($H95,'Cooling-Rack'!$A$2:$G$265,5,FALSE) -> 38.25 | N95: =VLOOKUP($H95,'Cooling-Rack'!$A$2:$G$265,7,FALSE) -> 6.75 | O95: 54 | P95: 0.85 | Q95: 0.15 | R95: RPP-R3-A4 | S95: RPP-R3-B4 | T95: RPDU-R3-A | U95: RPDU-R3R4-B | V95: UPS-02-A | W95: UPS-02-B | X95: BESS-01 | Y95: SWGR-01 | Z95: SWGR-02 | AA95: UTIL-01 | AB95: UTIL-02 | AC95: GEN-01 | AD95: GEN-02 | AE95: CC-R3 | AF95: BDL-R3 | AG95: BDL-RPDU-R3R4 | AH95: BDL-UPS-02 | AL95: 0 | AM95: =AL95/$L95*$M95 -> 0 | AN95: =AL95/$L95*$N95 -> 0 | AO95: 0 | AP95: =AO95/$L95*$M95 -> 0 | AQ95: =AO95/$L95*$N95 -> 0 | AR95: 30 | AS95: =AR95/$L95*$M95 -> 25.5 | AT95: =AR95/$L95*$N95 -> 4.5 | AU95: 30 | AV95: =AU95/$L95*$M95 -> 25.5 | AW95: =AU95/$L95*$N95 -> 4.5 | BA95: =$L95-$AI95 -> 45 | BB95: =$L95-$AL95 -> 45 | BC95: =$L95-$AO95 -> 45 | BD95: =$L95-$AR95 -> 15 | BE95: =$L95-$AU95 -> 15 | BF95: =$L95-$AX95 -> 45 | BG95: =BA95/$L95 -> 1 | BH95: =BB95/$L95 -> 1 | BI95: =BC95/$L95 -> 1 | BJ95: =BD95/$L95 -> 0.33333333 | BK95: =BE95/$L95 -> 0.33333333 | BL95: =BF95/$L95 -> 1 | BO95: DTC-RACK-R3-Z4E-R2-10 | BP95: =M95/0.9 -> 42.5 | BQ95: =IF($AI95>0, 1, 0) -> 0 | BR95: =IF($AL95>0, 1, 0) -> 0 | BS95: =IF($AO95>0, 1, 0) -> 0 | BT95: =IF($AR95>0, 1, 0) -> 1 | BU95: =IF($AU95>0, 1, 0) -> 1 | BV95: =IF(AX95>0, 1, 0) -> 0
A96: ZONE-R3-Z4E | B96: ROW-R3-Z4E-R2 | C96: 45 | F96: LL-R3-E | G96: AIRZONE-R3-E1 | H96: RACK-R3-Z4E-R2-11 | I96: POD-06 | J96: ="RACKPDU-"&H96&"-A" -> RACKPDU-RACK-R3-Z4E-R2-11-A | K96: ="RACKPDU-"&H96&"-B" -> RACKPDU-RACK-R3-Z4E-R2-11-B | L96: 45 | M96: =VLOOKUP($H96,'Cooling-Rack'!$A$2:$G$265,5,FALSE) -> 38.25 | N96: =VLOOKUP($H96,'Cooling-Rack'!$A$2:$G$265,7,FALSE) -> 6.75 | O96: 54 | P96: 0.85 | Q96: 0.15 | R96: RPP-R3-A4 | S96: RPP-R3-B4 | T96: RPDU-R3-A | U96: RPDU-R3R4-B | V96: UPS-02-A | W96: UPS-02-B | X96: BESS-01 | Y96: SWGR-01 | Z96: SWGR-02 | AA96: UTIL-01 | AB96: UTIL-02 | AC96: GEN-01 | AD96: GEN-02 | AE96: CC-R3 | AF96: BDL-R3 | AG96: BDL-RPDU-R3R4 | AH96: BDL-UPS-02 | AL96: 0 | AM96: =AL96/$L96*$M96 -> 0 | AN96: =AL96/$L96*$N96 -> 0 | AO96: 0 | AP96: =AO96/$L96*$M96 -> 0 | AQ96: =AO96/$L96*$N96 -> 0 | AR96: 30 | AS96: =AR96/$L96*$M96 -> 25.5 | AT96: =AR96/$L96*$N96 -> 4.5 | AU96: 30 | AV96: =AU96/$L96*$M96 -> 25.5 | AW96: =AU96/$L96*$N96 -> 4.5 | BA96: =$L96-$AI96 -> 45 | BB96: =$L96-$AL96 -> 45 | BC96: =$L96-$AO96 -> 45 | BD96: =$L96-$AR96 -> 15 | BE96: =$L96-$AU96 -> 15 | BF96: =$L96-$AX96 -> 45 | BG96: =BA96/$L96 -> 1 | BH96: =BB96/$L96 -> 1 | BI96: =BC96/$L96 -> 1 | BJ96: =BD96/$L96 -> 0.33333333 | BK96: =BE96/$L96 -> 0.33333333 | BL96: =BF96/$L96 -> 1 | BO96: DTC-RACK-R3-Z4E-R2-11 | BP96: =M96/0.9 -> 42.5 | BQ96: =IF($AI96>0, 1, 0) -> 0 | BR96: =IF($AL96>0, 1, 0) -> 0 | BS96: =IF($AO96>0, 1, 0) -> 0 | BT96: =IF($AR96>0, 1, 0) -> 1 | BU96: =IF($AU96>0, 1, 0) -> 1 | BV96: =IF(AX96>0, 1, 0) -> 0
A97: ZONE-R3-Z4E | B97: ROW-R3-Z4E-R2 | C97: 45 | F97: LL-R3-E | G97: AIRZONE-R3-E1 | H97: RACK-R3-Z4E-R2-12 | I97: POD-06 | J97: ="RACKPDU-"&H97&"-A" -> RACKPDU-RACK-R3-Z4E-R2-12-A | K97: ="RACKPDU-"&H97&"-B" -> RACKPDU-RACK-R3-Z4E-R2-12-B | L97: 45 | M97: =VLOOKUP($H97,'Cooling-Rack'!$A$2:$G$265,5,FALSE) -> 38.25 | N97: =VLOOKUP($H97,'Cooling-Rack'!$A$2:$G$265,7,FALSE) -> 6.75 | O97: 54 | P97: 0.85 | Q97: 0.15 | R97: RPP-R3-A4 | S97: RPP-R3-B4 | T97: RPDU-R3-A | U97: RPDU-R3R4-B | V97: UPS-02-A | W97: UPS-02-B | X97: BESS-01 | Y97: SWGR-01 | Z97: SWGR-02 | AA97: UTIL-01 | AB97: UTIL-02 | AC97: GEN-01 | AD97: GEN-02 | AE97: CC-R3 | AF97: BDL-R3 | AG97: BDL-RPDU-R3R4 | AH97: BDL-UPS-02 | AL97: 0 | AM97: =AL97/$L97*$M97 -> 0 | AN97: =AL97/$L97*$N97 -> 0 | AO97: 0 | AP97: =AO97/$L97*$M97 -> 0 | AQ97: =AO97/$L97*$N97 -> 0 | AR97: 30 | AS97: =AR97/$L97*$M97 -> 25.5 | AT97: =AR97/$L97*$N97 -> 4.5 | AU97: 30 | AV97: =AU97/$L97*$M97 -> 25.5 | AW97: =AU97/$L97*$N97 -> 4.5 | BA97: =$L97-$AI97 -> 45 | BB97: =$L97-$AL97 -> 45 | BC97: =$L97-$AO97 -> 45 | BD97: =$L97-$AR97 -> 15 | BE97: =$L97-$AU97 -> 15 | BF97: =$L97-$AX97 -> 45 | BG97: =BA97/$L97 -> 1 | BH97: =BB97/$L97 -> 1 | BI97: =BC97/$L97 -> 1 | BJ97: =BD97/$L97 -> 0.33333333 | BK97: =BE97/$L97 -> 0.33333333 | BL97: =BF97/$L97 -> 1 | BO97: DTC-RACK-R3-Z4E-R2-12 | BP97: =M97/0.9 -> 42.5 | BQ97: =IF($AI97>0, 1, 0) -> 0 | BR97: =IF($AL97>0, 1, 0) -> 0 | BS97: =IF($AO97>0, 1, 0) -> 0 | BT97: =IF($AR97>0, 1, 0) -> 1 | BU97: =IF($AU97>0, 1, 0) -> 1 | BV97: =IF(AX97>0, 1, 0) -> 0
A98: ZONE-R3-Z5E | B98: ROW-R3-Z5E-R1 | C98: 45 | F98: LL-R3-E | G98: AIRZONE-R3-E1 | H98: RACK-R3-Z5E-R1-01 | I98: POD-06 | J98: ="RACKPDU-"&H98&"-A" -> RACKPDU-RACK-R3-Z5E-R1-01-A | K98: ="RACKPDU-"&H98&"-B" -> RACKPDU-RACK-R3-Z5E-R1-01-B | L98: 45 | M98: =VLOOKUP($H98,'Cooling-Rack'!$A$2:$G$265,5,FALSE) -> 38.25 | N98: =VLOOKUP($H98,'Cooling-Rack'!$A$2:$G$265,7,FALSE) -> 6.75 | O98: 54 | P98: 0.85 | Q98: 0.15 | R98: RPP-R3-A3 | S98: RPP-R3-B1 | T98: RPDU-R3-A | U98: RPDU-R3R4-B | V98: UPS-02-A | W98: UPS-02-B | X98: BESS-01 | Y98: SWGR-01 | Z98: SWGR-02 | AA98: UTIL-01 | AB98: UTIL-02 | AC98: GEN-01 | AD98: GEN-02 | AE98: CC-R3 | AF98: BDL-R3 | AG98: BDL-RPDU-R3R4 | AH98: BDL-UPS-02 | AL98: 0 | AM98: =AL98/$L98*$M98 -> 0 | AN98: =AL98/$L98*$N98 -> 0 | AO98: 0 | AP98: =AO98/$L98*$M98 -> 0 | AQ98: =AO98/$L98*$N98 -> 0 | AR98: 30 | AS98: =AR98/$L98*$M98 -> 25.5 | AT98: =AR98/$L98*$N98 -> 4.5 | AU98: 30 | AV98: =AU98/$L98*$M98 -> 25.5 | AW98: =AU98/$L98*$N98 -> 4.5 | BA98: =$L98-$AI98 -> 45 | BB98: =$L98-$AL98 -> 45 | BC98: =$L98-$AO98 -> 45 | BD98: =$L98-$AR98 -> 15 | BE98: =$L98-$AU98 -> 15 | BF98: =$L98-$AX98 -> 45 | BG98: =BA98/$L98 -> 1 | BH98: =BB98/$L98 -> 1 | BI98: =BC98/$L98 -> 1 | BJ98: =BD98/$L98 -> 0.33333333 | BK98: =BE98/$L98 -> 0.33333333 | BL98: =BF98/$L98 -> 1 | BO98: DTC-RACK-R3-Z5E-R1-01 | BP98: =M98/0.9 -> 42.5 | BQ98: =IF($AI98>0, 1, 0) -> 0 | BR98: =IF($AL98>0, 1, 0) -> 0 | BS98: =IF($AO98>0, 1, 0) -> 0 | BT98: =IF($AR98>0, 1, 0) -> 1 | BU98: =IF($AU98>0, 1, 0) -> 1 | BV98: =IF(AX98>0, 1, 0) -> 0
