Workbook

Sheet Sheet1
A1: Node Type | B1: Panel Section (Box) | C1: iSET | D1: Variable Name | E1: Variable name display in panel | F1: Unit | G1: Display Format & notes | H1: Source data cube (temporary) | I1: Find-By Column Name1 (temporary) | J1: Special Comments | K1: Find-By Column Name2 (temporary) | L1: Special Comments | M1: Variable Column Name (temporary) | N1: Special Comments
A2: Rack | B2: Capacity | C2: Operational Capacity
D3: Rack_Circuit_Capacity_(rated) | E3: as-is, replace "_" with space | F3: kW | G3: basic | H3: Master_Rack | I3: Rack | J3: Find by Rack ID | M3: Rack_Circuit_Capacity_(rated)
D4: Rack_Circuit_Capacity_(design) | E4: as-is, replace "_" with space | F4: kW | G4: basic | H4: Master_Rack | I4: Rack | J4: Find by Rack ID | M4: Rack_Circuit_Capacity_(design)
A5: Rack | B5: Load Allocation | C5: Load Allocation
D6: Allocated_ITLoad | E6: as-is, replace "_" with space | F6: kW | G6: Basic | H6: Master_Rack | I6: Rack | J6: Find by Rack ID | M6: ITL-SJ-Meridian-C01-PP01, ITL-SJ-Pacific-C01-PD01, ITL-SJ-Pacific-C01-PD02, ITL-SJ-Pacific-C01-PD03, ITL-SJ-Pacific-C01-PD04, ITL-SJ-Keystone-C01-PP01 | N6: If the Rack data panel is viewed while in the Spatial Topology or Whitespace Blueprint navigation, use any column that is for a Placement Plan (PP). If the Rack data panel is viewed while in the Deployment Blueprint navigation, use the exact column that represents the current Placement Plan (PP) or Placement Draft (PD) selected in the navigation
D7: Allocated_AirCool_Load | E7: as-is, replace "_" with space | F7: kW | G7: Basic | H7: Master_Rack | I7: Rack | J7: Find by Rack ID | M7: ACL-SJ-Meridian-C01-PP01, ACL-SJ-Pacific-C01-PD01, ACL-SJ-Pacific-C01-PD02, ACL-SJ-Pacific-C01-PD03, ACL-SJ-Pacific-C01-PD04, ACL-SJ-Keystone-C01-PP01
D8: Allocated_LiquidCool_Load | E8: as-is, replace "_" with space | F8: kW | G8: Basic | H8: Master_Rack | I8: Rack | J8: Find by Rack ID | M8: LCL-SJ-Meridian-C01-PP01, LCL-SJ-Pacific-C01-PD01, LCL-SJ-Pacific-C01-PD02, LCL-SJ-Pacific-C01-PD03, LCL-SJ-Pacific-C01-PD04, LCL-SJ-Keystone-C01-PP01
D9: TheorMax_ITLoad | G9: Basic | H9: Master_Rack | I9: Rack | J9: Find by Rack ID
A10: Rack | B10: Capacity Margins | C10: Capacity Margin
D11: Local_Capacity_Margin | E11: as-is, replace "_" with space | F11: kW | G11: horizontal bar. Data label shows Allocated_ITLoad/ Rack_Circuit_Capacity_(design), and the margin %. E.g. 250/ 300 (83%). Rack_Circuit_Capacity_(design) is already defined in the above Capacity section | H11: Local_Capacity_Margin = Rack_Circuit_Capacity_(design) - Allocated_ITLoad
D12: Local_Capacity_Margin% | E12: as-is, replace "_" with space | F12: Percent | H12: These two variables are already defined in the above sections
A13: Rack | B13: Capacity Margins | C13: Upstream Capacity Margin
D14: Upstream_Capacity | E14: Use the actual upstream node ID/ name | F14: kW | G14: Horizontal bars. Data label shows upstream node load/ capacity and the margin % e.g. 250/300 (83%) If margin is negative, show as red | H14: Constraints | I14: Constraint Node | J14: Find by the upstream Node ID; Identify the relavant upstream Node ID using the Upstream Type and Upstream tables | M14: Operational Capacity
D15: Upstream_Load | E15: Use the actual upstream node ID/ name | F15: kW | H15: Constraints | I15: Constraint Node | J15: Find by the upstream Node ID; Identify the relavant upstream Node ID using the Upstream Type and Upstream tables | M15: TOTAL LOAD ALL PP, TOTAL LOAD with SJ-PACIFIC-C01-PD01, TOTAL LOAD with SJ-PACIFIC-C01-PD02, TOTAL LOAD with SJ-PACIFIC-C01-PD03, TOTAL LOAD with SJ-PACIFIC-C01-PD04 | N15: If the Rack data panel is viewed while in the Spatial Topology or Whitespace Blueprint navigation, use TOTAL LOAD ALL PP If the Rack data panel is viewed while in the Deployment Blueprint navigation, and a Deploymet Plan is selected, also use TOTAL LOAD ALL PP. If the Rack data panel is viewed while in the Deployment Blueprint navigation, and a Deploymet DRAFT is selected, use TOTAL LOAD with [placement draft ID]
D16: Upstream_Capacity_Margin | F16: kW | H16: Upstream_Capacit_Margin = Upstream_Capacity - Upstream_Load FOR EACH UPSTREAM NODE
D17: Upstream_Capacity_Margin% | F17: Percent | H17: The two variables for each upstream node is already defined above
A19: Rack | B19: Other Parameters | C19: Other Design Parameters
D20: Rack_AirCool_Fraction | E20: as-is, replace "_" with space | F20: Percent | G20: Bar chart with two colors | H20: Master_Rack | I20: Rack | J20: Find by Rack ID | M20: Rack_AirCool_Fraction
D21: Rack_LiquidCool_Fraction | E21: as-is, replace "_" with space | F21: Percent | H21: Master_Rack | I21: Rack | J21: Find by Rack ID | M21: Rack_LiquidCool_Fraction
A22: Row | B22: Capacity | C22: Operational Capacity
D23: Rack_Circuit_Capacity_(design) | E23: as-is, replace "_" with space | F23: kW | G23: basic | H23: Constraints | I23: Constraint Node | J23: Find by Row ID | M23: Rack_Circuit_Capacity_(design)
A24: Row | B24: Load Allocation | C24: Load Allocation
D25: Rack_Count | E25: as-is, replace "_" with space | F25: Count | G25: basic | H25: Constraints | I25: Constraint Node | J25: Find by Row ID | M25: TOTAL COUNT ALL PP, TOTAL COUNT with SJ-PACIFIC-C01-PD01, TOTAL COUNT with SJ-PACIFIC-C01-PD02, TOTAL COUNT with SJ-PACIFIC-C01-PD03, TOTAL COUNT with SJ-PACIFIC-C01-PD04 | N25: If the Row data panel is viewed while in the Spatial Topology or Whitespace Blueprint navigation, use TOTAL COUNT ALL PP If the row data panel is viewed while in the Deployment Blueprint navigation, a Deploymet Plan is selected, also use TOTAL COUNT ALL PP. If the row data panel is viewed while in the Deployment Blueprint navigation, and a Deploymet DRAFT is selected, use TOTAL COUNT with [placement draft ID]
D26: Allocated_ITLoad | E26: as-is, replace "_" with space | F26: kW | G26: basic | H26: Constraints | I26: Constraint Node | J26: Find by Row ID | M26: TOTAL LOAD ALL PP, TOTAL LOAD with SJ-PACIFIC-C01-PD01, TOTAL LOAD with SJ-PACIFIC-C01-PD02, TOTAL LOAD with SJ-PACIFIC-C01-PD03, TOTAL LOAD with SJ-PACIFIC-C01-PD04 | N26: If the Row data panel is viewed while in the Spatial Topology or Whitespace Blueprint navigation, use TOTAL LOAD ALL PP If the row data panel is viewed while in the Deployment Blueprint navigation, a Deploymet Plan is selected, also use TOTAL LOAD ALL PP. If the row data panel is viewed while in the Deployment Blueprint navigation, and a Deploymet DRAFT is selected, use TOTAL LOAD with [placement draft ID]
A27: CDU | B27: Capacity | C27: Device Capacity
D28: Rated_Cooling_Capacity | E28: as-is, replace "_" with space | F28: kW | G28: basic | H28: Constraints | I28: Constraint Node | J28: Find by CDU ID | M28: Device Rating
D29: Pump_Capacity | E29: as-is, replace "_" with space | F29: L/s | G29: basic | H29: Constraints | I29: Constraint Node | J29: Find by CDU ID | M29: CDU.Pump_Capacity (L/s)
A30: RPP | B30: Capacity | C30: Operational Capacity
D31: RPP_Panel_Capacity_(rated) | E31: as-is, replace "_" with space | F31: kW | G31: basic | H31: Constraints | I31: Constraint Node | J31: Find by RPP ID | M31: Device Rating
D32: RPP_Panel_Capacity_(design) | E32: as-is, replace "_" with space | F32: kW | G32: basic | H32: Constraints | I32: Constraint Node | J32: Find by RPP ID | M32: Operational Capacity
D33: RPP_BreakerPole_Capacity | E33: as-is, replace "_" with space | F33: Count | G33: basic | H33: Constraints | I33: Constraint Node | J33: Find by RPP ID | M33: RPP_BreakerPole_Capacity
A34: RPP | B34: Load Allocation | C34: Load Allocation
D35: Rack_Count | E35: as-is, replace "_" with space | F35: Count | G35: basic | H35: Constraints | I35: Constraint Node | J35: Find by RPP ID | M35: Same methods used for Row Load Allocation | N35: Same methods used for Row Load Allocation
D36: Allocated_ITLoad | E36: as-is, replace "_" with space | F36: kW | G36: basic | H36: Constraints | I36: Constraint Node | J36: Find by RPP ID | M36: Same as for Row Load Allocation | N36: Same as for Row Load Allocation
A37: RPP | B37: Capacity Margins | C37: Capacity Margin
D38: Device_Capacity_Margin | E38: as-is, replace "_" with space | F38: kW | G38: horizontal bar. Data label shows Allocated_ITLoad/ RPP_Panel_Capacity_(design), and the margin %. | H38: Device_Capacity_Margin = RPP_Panel_Capacity_(design) - Allocated_ITLoad
D39: Device_Capacity_Margin% | E39: as-is, replace "_" with space | F39: Percent | H39: These two variables are already defined in the above sections
A40: RPP | B40: Capacity Margins | C40: Upstream Capacity Margin
D41: Upstream_Capacity | E41: Use the actual upstream node ID/ name | F41: kW | G41: Horizontal bars. Data label shows upstream node load/ capacity and the margin % e.g. 250/300 (83%) If margin is negative, show as red | I41: Same methods used for Rack upstream capacity margin | L41: Same methods used for Rack upstream capacity margin
...

Sheet Panel Structure
A1: NODE DATA PANEL - CAPACITY TAB
A3: Panel Sections (these are boxes, one box per section)
A5: Capacity
A6: Load Allocation
A7: Capacity Margins
A8: Other Parameters

Sheet Capacity (Rack)
A3: Variable Group | B3: Capacity variables Rack
A4: Data Panel Section (Box) | B4: Capacity
A5: iSET name | B5: Operational Capacity
A6: Display Format & notes | B6: basic (simple variable name and value)
A7: Source data table (temporary) | B7: Master_Rack
A8: Find-By Column Name1 (temporary) | B8: Rack (Find by the Rack ID)
A13: Node Tye | B13: Variable | C13: Variable Column Name (temporary) | D13: Unit | E13: Special comments
A14: Rack | B14: Rack_Circuit_Capacity_(rated) | C14: Rack_Circuit_Capacity_(rated) | D14: kW
A15: Rack | B15: Rack_Circuit_Capacity_(design) | C15: Rack_Circuit_Capacity_(design) | D15: kW

Sheet Capacity (2)
A3: Variable Group | B3: Capacity variables for Row, RPP, AZ, LL, RPDU, UPS, CDIST, CC | C3: Capacity variables for CDU, Air Cooling Unit
A4: Data Panel Section (Box) | B4: Capacity | C4: Capacity
A5: iSET name | B5: Operational Capacity | C5: Device Capacity
A6: Display Format & notes | B6: basic (simple variable name and value) | C6: basic (simple variable name and value)
A7: Source data table (temporary) | B7: Constraints | C7: Constraints
A8: Find-By Column Name1 (temporary) | B8: Costraint Node (find by the Node ID) | C8: Costraint Node (find by the Node ID)
A13: Node Tye | B13: Variable | C13: Variable Column Name (temporary) | D13: Unit | E13: Special comments
A14: RPP | B14: RPP_Panel_Capacity_(rated) | C14: Device Rating | D14: kW
A15: RPP | B15: RPP_Panel_Capacity_(design) | C15: Operational Capacity | D15: kW
A16: RPP | B16: RPP_BreakerPole_Capacity | C16: RPP_BreakerPole_Capacity | D16: count
A17: RPP | B17: Rack Positions | C17: computed | D17: count
A18: Air Zone | B18: AirZone_Cooling_Capacity | C18: Operational Capacity | D18: kW
A19: Air Zone | B19: Maximum_Air_Flow | C19: AirZone.Maximum_Air_Flow (m3/s) | D19: m3/s
A20: Air Zone | B20: Rack Positions | C20: computed | D20: count
A21: Liquid Loop | B21: LL_Cooling_Capacity | C21: Operational Capacity | D21: kW
A22: Liquid Loop | B22: Maximum_Flow_Rate | C22: LL.Maximum_Flow_Rate | D22: L/s
A23: Liquid Loop | B23: Rack Positions | C23: computed | D23: count
A24: Room PDU | B24: RPDU_Transformer_Rating | C24: Device Rating | D24: kW
A25: Room PDU | B25: RPDU_Design_Capacity | C25: Device Capacity (design) | D25: kW
... A31: UPS | B31: Rack Positions | C31: computed | D31: count
A32: Cooling Distribution | B32: Cooling Capacity | C32: Operational Capacity | D32: kW | E32: for each cooling distribution, only one of these three capacities is available
A33: Cooling Distribution | B33: Liquid_Cooling_Capacity | C33: Operational Capacity | D33: kW | E33: for each cooling distribution, only one of these three capacities is available
A34: Cooling Distribution | B34: Air_Cooling_Capacity | C34: Operational Capacity | D34: kW | E34: for each cooling distribution, only one of these three capacities is available
A35: Cooling Distribution | B35: Rack Positions | C35: computed | D35: count
A36: Capacity Cell | B36: Capacity_Envelope | C36: Operational Capacity | D36: kW
A37: Capacity Cell | B37: Power_Capacity | C37: CC Power Capacity | D37: kW
A38: Capacity Cell | B38: Thermal_Capacity | C38: CC Thermal Capacity | D38: kW
A39: Capacity Cell | B39: Rack Positions | C39: computed | D39: count
A40: CDU | B40: Rated_Cooling_Capacity | C40: Device Rating | D40: kW
A41: CDU | B41: Pump_Capacity | C41: CDU.Pump_Capacity (L/s) | D41: L/s
A42: Air Cooling Unit | B42: Rated_Cooling_Capacity | C42: Device Rating | D42: kW
A43: Air Cooling Unit | B43: Maximum_Air_Flow | C43: AirCoolUnit.Maximum_Air_Flow (m3/s) | D43: m3/s
A44: Row | B44: Rack_Circuit_Capacity_(design) | C44: Rack_Circuit_Capacity_(design) | D44: kW
A45: Row | B45: Rack Positions | C45: computed | D45: count

Sheet Load Alloc (Rack)
A3: Variable Group | B3: Capacity variables for Racks
A4: Data Panel Section (Box) | B4: Load Allocation
A5: iSET name | B5: Load Allocation
A6: Display Format & notes | B6: basic (simple variable name and value)
A7: Source data table (temporary) | B7: Master_Rack
A8: Find-By Column Name1 (temporary) | B8: Rack (find by Rack ID)
B9: TOTAL COUNT ALL PP, TOTAL COUNT with SJ-PACIFIC-C01-PD01, TOTAL COUNT with SJ-PACIFIC-C01-PD02, TOTAL COUNT with SJ-PACIFIC-C01-PD03, TOTAL COUNT with SJ-PACIFIC-C01-PD04
A12: Node Tye | B12: Variable | C12: Variable Column Name (temporary) | D12: Unit | E12: Special comments
A13: Rack | B13: Allocated_ITLoad | C13: ITL-SJ-Meridian-C01-PP01, ITL-SJ-Pacific-C01-PD01, ITL-SJ-Pacific-C01-PD02, ITL-SJ-Pacific-C01-PD03, ITL-SJ-Pacific-C01-PD04, ITL-SJ-Keystone-C01-PP01 | D13: kW | E13: see conditions
A14: Rack | B14: Allocated_AirCool_Load | C14: ACL-SJ-Meridian-C01-PP01, ACL-SJ-Pacific-C01-PD01, ACL-SJ-Pacific-C01-PD02, ACL-SJ-Pacific-C01-PD03, ACL-SJ-Pacific-C01-PD04, ACL-SJ-Keystone-C01-PP01 | D14: kW | E14: see conditions
A15: Rack | B15: Allocated_LiquidCool_Load | C15: LCL-SJ-Meridian-C01-PP01, LCL-SJ-Pacific-C01-PD01, LCL-SJ-Pacific-C01-PD02, LCL-SJ-Pacific-C01-PD03, LCL-SJ-Pacific-C01-PD04, LCL-SJ-Keystone-C01-PP01 | D15: kW | E15: see conditions
A17: Conditions
A18: IF
A19: navigation = {Spatial Topology, Whitespace Blueprint}
A20: OR (naviation = Deployment Blueprint, AND a Deployment Plan or its children is selected in the navigation)
A21: THEN
A22: Use: (ITL-SJ-Meridian-C01-PP01 + ITL-SJ-Keystone-C01-PP01) for ITLoad
A23: Use: (ACL-SJ-Meridian-C01-PP01 + ACL-SJ-Keystone-C01-PP01) for AirCool Load
A24: Use: (LCL-SJ-Meridian-C01-PP01 + LCL-SJ-Keystone-C01-PP01) for LiquidCool Load
A26: ELSE
A27: Use: ITL-[deplooyment draft name] +((ITL-SJ-Meridian-C01-PP01 + ITL-SJ-Keystone-C01-PP01)) for IT load
A28: Use: ACL-[deplooyment draft name] + (ACL-SJ-Meridian-C01-PP01 + ACL-SJ-Keystone-C01-PP01) for AirCool load
A29: Use: LCL-[deplooyment draft name] + (LCL-SJ-Meridian-C01-PP01 + LCL-SJ-Keystone-C01-PP01) for LiquidCool load

Sheet Load Alloc (2)
A3: Variable Group | B3: Capacity variables for Row, RPP, AZ, LL, RPDU, UPS, CDIST, CC
A4: Data Panel Section (Box) | B4: Load Allocation
A5: iSET name | B5: Load Allocation
A6: Display Format & notes | B6: basic (simple variable name and value)
A7: Source data table (temporary) | B7: Constraints
A8: Find-By Column Name1 (temporary) | B8: Costraint Node (find by the Node ID)
A9: Variable Column Names | B9: TOTAL COUNT ALL PP, TOTAL COUNT with SJ-PACIFIC-C01-PD01, TOTAL COUNT with SJ-PACIFIC-C01-PD02, TOTAL COUNT with SJ-PACIFIC-C01-PD03, TOTAL COUNT with SJ-PACIFIC-C01-PD04
A10: Conditions
A11: IF
A12: navigation = {Deployment Blueprint}
A13: AND a Deployment Draft or its children is selected in the navigation
A14: THEN
A15: Use columns: TOTAL COUNT with [deployment draft name]
A16: ELSE
A17: Use column: TOTAL COUNT ALL PP
A18: * this means if navigation = {Spatial Topology, Whitespace Blueprint}, also use the TOTAL COUNT with [deployment draft name] columns
A21: Node Tye | B21: Variable | C21: Variable Column Name (temporary) | D21: Unit | E21: Special comments
A22: Row | B22: Rack_Count | C22: as defined above | D22: count
A23: Row | B23: Allocated_ITLoad | C23: as defined above | D23: kW
A24: RPP | B24: Rack_Count | C24: as defined above | D24: count
A25: RPP | B25: Allocated_ITLoad | C25: as defined above | D25: kW
A26: Air Zone | B26: Rack_Count | C26: as defined above | D26: count
A27: Air Zone | B27: Allocated_AirCool_Load | C27: as defined above | D27: kW
A28: Liquid Loop | B28: Rack_Count | C28: as defined above | D28: count
A29: Liquid Loop | B29: Allocated_LiquidCool_Load | C29: as defined above | D29: kW
A30: Room PDU | B30: Rack_Count | C30: as defined above | D30: count
A31: Room PDU | B31: Allocated_ITLoad | C31: as defined above | D31: kW
A32: UPS | B32: Rack_Count | C32: as defined above | D32: count
A33: UPS | B33: Allocated_ITLoad | C33: as defined above | D33: kW
... A35: Capacity Cell | B35: Allocated_ITLoad | C35: as defined above | D35: kW
A36: Capacity Cell | B36: Allocated_AirCool_Load | C36: calculated: Allocated_AirCool_Load of all Air Zones in the Capacity Cell
A37: Capacity Cell | B37: Allocated_LiquidCool_Load | C37: calculated: Allocated_LiquidCool_Load of all Liquid Loops in the Capacity Cell
A38: Room Bundle | B38: Rack_Count | C38: calculate by SUM of the capacity cell Rack_Counts
A39: Room Bundle | B39: Allocated_ITLoad | C39: calculate by SUM of the capacity cell Allocated_ITLoad
A40: Room PDU Bundle | B40: Rack_Count | C40: calculate by SUM of the capacity cell Rack_Counts
A41: Room PDU Bundle | B41: Allocated_ITLoad | C41: calculate by SUM of the capacity cell Allocated_ITLoad
A42: UPS Bundle | B42: Rack_Count | C42: calculate by SUM of the capacity cell Rack_Counts
A43: UPS Bundle | B43: Allocated_ITLoad | C43: calculate by SUM of the capacity cell Allocated_ITLoad

Sheet CM
A3: Variable Group | B3: Capacity Margins variables for Rack, RPP, Air Zone, Liquid Loop, Room PDU, UPS, Capacity Cell, Room Bundle, Room PDU Bundle, UPS Bundle
A4: Data Panel Section (Box) | B4: Capacity Margins
A5: iSET name | B5: Capaity Margin
A6: Display Format & notes | B6: Horizontal bars with node name. Data label shows allocated_load/ capacity and the margin % e.g. 250/300 (83%) If margin is negative, show as red
A7: Source data table (temporary) | B7: Computed
A13: Node Tye | B13: Variable | C13: Formula | D13: Unit | E13: Special comments
A14: Rack | B14: Local_Capacity_Margin | C14: = Rack_Circuit_Capacity_(design) - Allocated_ITLoad
A15: Rack | B15: Local_Capacity_Margin% | C15: = Local_Capacity_Margin/ Rack_Circuit_Capacity_(design)
A16: RPP | B16: Local_Capacity_Margin | C16: = RPP_Panel_Capacity_(design) - Allocated_ITLoad
A17: RPP | B17: Local_Capacity_Margin% | C17: = Local_Capacity_Margin/ RPP_Panel_Capacity_(design)
A18: Air Zone | B18: Local_Capacity_Margin | C18: = AirZone_Cooling_Capacity - Allocated_AirCool_Load
A19: Air Zone | B19: Local_Capacity_Margin% | C19: = Local_Capacity_Margin/ AirZone_Cooling_Capacity
A20: Liquid Loop | B20: Local_Capacity_Margin | C20: = LL_Cooling_Capacity - Allocated_LiquidCool_Load
A21: Liquid Loop | B21: Local_Capacity_Margin% | C21: = Local_Capacity_Margin/ LL_Cooling_Capacity
A22: Room PDU | B22: Local_Capacity_Margin | C22: = RPDU_Operational_Cap - Allocated_ITLoad
A23: Room PDU | B23: Local_Capacity_Margin% | C23: = Local_Capacity_Margin/ RPDU_Operational_Cap
A24: Room PDU | B24: Device_Capacity_Margin | C24: = RPDU_Design_Capacity - Allocated_ITLoad
A25: Room PDU | B25: Device_Capacity_Margin% | C25: = Device_Capacity_Margin/ RPDU_Design_Capacity
... A46: UPS Bundle | B46: Bundle_Margin% | C46: = Bundle_Margin/ Capacity_Envelope

Sheet UpstreamSubdomainCM
A3: Variable Group | B3: Upstream Capacity Margins variables for Rack, RPP, Air Zone, Liquid Loop, Room PDU, UPS, Capacity Cell, Room Bundle, Room PDU Bundle, UPS Bundle
A4: Data Panel Section (Box) | B4: Capacity Margins
A5: iSET name | B5: Upstream Capacity Margin
A6: Display Format & notes | B6: Horizontal bars with node name. Data label shows allocated_load/ capacity and the margin % e.g. 250/300 (83%) If margin is negative, show as red
A7: Source data table (temporary) | B7: Computed
A9: Step 1
A10: Finde relevant upstream Nodes | B10: for each node, the its relevant upstream nodes should be found in the topologies. They are a subset of all the upstream nodes
A11: Use table | B11: Upstream Type | C11: to find for any given node, which upstream node types are relevant
A12: use table | B12: Upstream | C12: to find for any given node, which upstream node instances are linked (so we can bypass the topology traversal with the data file)
A14: Step 2
A15: Get the capacity, allocated load, and capacity margins from those nodes and display. Make sure to pick the capacity variable that is used to compute the capacity margin (not device margin)
A16: the capacity margins of those nodes should already have been computed and can be used
A19: Variable Group | B19: Subdomain Capacity Margins variables for Room Bundle, Room PDU Bundle, UPS Bundle
A20: Same process as above
A23: Node Tye | B23: Variable
A24: Rack, RPP, Air Zone, Liquicd Loop, Room PDU, UPS, Capacity Cell, Room Bundle, Room PDU Bundle, UPS Bundle | B24: Upstream_Capacity
B25: Upstream_Load
B26: Upstream_Capacity_Margin
B27: Upstream_Capacity_Margin%
A28: Capacity Cell, Room Bundle, Room PDU Bundle, UPS Bundle | B28: Subdomain_Capacity
B29: Subdomain_Load
B30: Subdomain_Capacity_Margin
B31: Subdomain_Capacity_Margin%

Sheet Other
A3: Variable Group | B3: Other Parameters for various node types
A4: Data Panel Section (Box) | B4: Other Parameters
A5: iSET name | B5: Other Design Parameters
A6: Display Format & notes | B6: basic (simple variable name and value)
A7: Find-By Column Name1 (temporary) | B7: Costraint Node (find by the Node ID)
A12: Node Tye | B12: Variable | C12: Source data table (temporary) | D12: Variable Column Name (temporary) | E12: Unit | F12: Special comments
A13: Rack | B13: Rack_AirCool_Fraction | C13: Master_Rack | D13: Rack_AirCool_Fraction
A14: Rack | B14: Rack_LiquidCool_Fraction | C14: Master_Rack | D14: Rack_LiquidCool_Fraction
A15: Air Zone | B15: Rack_Inlet_Setpoint | C15: Constraints | D15: Rack_Inlet_Setpoint
A16: Air Zone | B16: ColdAisle_Supply_Temp | C16: Constraints | D16: ColdAisle_Supply_Temp
A17: Air Zone | B17: Rack_DeltaT_(design) | C17: Constraints | D17: Rack_DeltaT_(design) (celsius)
A18: Liquid Loop | B18: Loop_Supply_Setpoint | C18: Constraints | D18: Loop_Supply_Setpoint
A19: Liquid Loop | B19: Loop_DeltaT_(design) | C19: Constraints | D19: Loop_DeltaT_(design) (celcius)
A20: RDHx | B20: RDHx_MaxHeat_Removal | C20: Master_Rack | D20: RDHx_MaxHeat_Removal
A21: DTC | B21: DTC_MaxCool_Capacity | C21: Master_Rack | D21: DTC_MaxCool_Capacity

Sheet BDLs
A2: Mapping Data Variables to the Bundle Nodes Data Panels (Room Bundles, Room PDU Bundles, UPS Bundles)
E9: Capacity Envelope of the Bundle
E11: Number of capacity cells in the Bundle
E13: Rack Positions of the Bundle
E14: List of Capacity Cells in the Bundle
E15: If the Capacity Cell is only used in Deployment Drafts, or not used, show "not Commited" | M15: If the Capacity Cell use by an Deployment Plan, show it as Committed to the Deployment and Cluster
E16: Capacity Envelope of the CC
E17: Rack Positions of the CC
M19: Cell Utilization% of the CC
E20: Load = Allocated Load of the CC
E21: Cell Envelope = Capacity Envelope of the CC
E23: Rack = Rack Count of the CC
E24: Rack Postion of the CC

Sheet ClusterManifest
A1: Deployment | B1: Cluster | C1: Rack Role | D1: Type | E1: Count | F1: Target kW | G1: Power Redundancy | H1: Cooling Mode | I1: Cooling Redundancy
A2: Meridian | B2: SJ-Meridian-C01 | C2: Compute | D2: GPU | E2: 18 | F2: 15 | G2: N | H2: Air, RDHx | I2: N
A3: Meridian | B3: SJ-Meridian-C01 | C3: Compute | D3: GPU | E3: 18 | F3: 10 | G3: N | H3: Air, RDHx | I3: N
A4: Pacific | B4: SJ-Pacific-C01 | C4: Compute | D4: GPU | E4: 52 | F4: 30 | G4: 2N | H4: Air, DTC | I4: N+1
A5: Keystone | B5: SJ-Keystone-C01 | C5: Compute | D5: GPU | E5: 23 | F5: 60 | G5: 2N | H5: Air, DTC | I5: N+1
A6: Keystone | B6: SJ-Keystone-C01 | C6: Storage | D6: CPU | E6: 1 | F6: 15 | G6: 2N | H6: Air, DTC | I6: N+1
A7: Keystone | B7: SJ-Keystrone-C02 | C7: Compute | D7: GPU | E7: 23 | F7: 60 | G7: 2N | H7: Air, DTC | I7: N+1
A8: Keystone | B8: SJ-Keystrone-C02 | C8: Storage | D8: CPU | E8: 1 | F8: 15 | G8: 2N | H8: Air, DTC | I8: N+1

Sheet Placement
D1: SJ-Pacific-C01-PD01
A2: Field Type | B2: Field Name | C2: SJ-Meridian-C01-PP01 | D2: SJ-Pacific-C01-PD01 | E2: SJ-Pacific-C01-PD02 | F2: SJ-Pacific-C01-PD03 | G2: SJ-Pacific-C01-PD04 | H2: SJ-Keystone-C01-PP01
A3: Load Requested | B3: kW Requested | C3: =ClusterManifest!E2*ClusterManifest!F2+ClusterManifest!E3*ClusterManifest!F3 -> 450 | D3: =ClusterManifest!E4*ClusterManifest!F4 -> 1560 | E3: =D3 -> 1560 | F3: =E3 -> 1560 | G3: =F3 -> 1560 | H3: =ClusterManifest!E5*ClusterManifest!F5+ClusterManifest!E6*ClusterManifest!F6 -> 1395
A4: Allocated ITLoad | B4: kW Placed | C4: =C3 -> 450 | D4: =D3 -> 1560 | E4: =D4 -> 1560 | F4: =E4 -> 1560 | G4: =F4 -> 1560 | H4: =H3 -> 1395
A5: Rack Requested | B5: Rack Requested | C5: =ClusterManifest!E2+ClusterManifest!E3 -> 36 | D5: =ClusterManifest!E4 -> 52 | E5: =D5 -> 52 | F5: =E5 -> 52 | G5: =F5 -> 52 | H5: =ClusterManifest!E5+ClusterManifest!E6 -> 24
A6: Rack Count | B6: Rack Placed | C6: =C5 -> 36 | D6: =D5 -> 52 | E6: =E5 -> 52 | F6: =F5 -> 52 | G6: =G5 -> 52 | H6: =H5 -> 24
A7: Cooling Mode | B7: Cooling Mode | C7: =ClusterManifest!H2 -> Air, RDHx | D7: =ClusterManifest!H4 -> Air, DTC | E7: =D7 -> Air, DTC | F7: =E7 -> Air, DTC | G7: =F7 -> Air, DTC | H7: =ClusterManifest!H5 -> Air, DTC
A8: Power Redundancy | B8: Power Reduncancy | C8: =ClusterManifest!G2 -> N | D8: =ClusterManifest!G4 -> 2N | E8: =D8 -> 2N | F8: =E8 -> 2N | G8: =F8 -> 2N | H8: =ClusterManifest!G5 -> 2N
A9: Rack Role1 | B9: Role | C9: Compute | D9: Compute | E9: Compute | F9: Compute | G9: Compute | H9: Compute
A10: Compute.Target kW | B10: Target kW | C10: =ClusterManifest!F2 -> 15 | D10: =ClusterManifest!F4 -> 30 | E10: =D10 -> 30 | F10: =E10 -> 30 | G10: =F10 -> 30 | H10: 60
A11: Compute.Count | B11: Count | C11: =ClusterManifest!E2 -> 18 | D11: =ClusterManifest!E4 -> 52 | E11: =D11 -> 52 | F11: =E11 -> 52 | G11: =F11 -> 52 | H11: 23
A12: Compute.Placed | B12: Placed | C12: =C11 -> 18 | D12: =D11 -> 52 | E12: =D12 -> 52 | F12: =E12 -> 52 | G12: =F12 -> 52 | H12: 23
A13: Compute.Cooling | B13: Cooling | C13: =ClusterManifest!H2 -> Air, RDHx | D13: =ClusterManifest!H4 -> Air, DTC | E13: =D13 -> Air, DTC | F13: =E13 -> Air, DTC | G13: =F13 -> Air, DTC | H13: =H7 -> Air, DTC
A14: Compute.Pleacement | B14: Placement | C14: CC-R1R2 | D14: CC-R3 | E14: =D14 -> CC-R3 | F14: =E14 -> CC-R3 | G14: =F14 -> CC-R3 | H14: CC-R5E
A15: Rack Role2 | B15: Role | C15: Compute | H15: Storage
A16: Storage.Target kW | B16: Target kW | C16: =ClusterManifest!F3 -> 10 | H16: =ClusterManifest!F6 -> 15
A17: Storage.Count | B17: Count | C17: =ClusterManifest!E3 -> 18 | H17: 1
A18: Storage.Placed | B18: Placed | C18: =C17 -> 18 | H18: 1
A19: Storage.Cooling | B19: Cooling | C19: =ClusterManifest!H3 -> Air, RDHx | H19: =H7 -> Air, DTC
A20: Storage.Pleacement | B20: Placement | C20: CC-R1R2 | H20: CC-R5E
A22: Capacity Cell1 | B22: Capacity Cells | C22: CC-R1R2 | D22: CC-R3 | E22: CC-R3 | F22: CC-R3 | G22: CC-R3
A23: Capacity Cell.kW guaranteed | B23: kW guaranteed | C23: 920 | D23: 3680 | E23: 3680 | F23: 3680 | G23: 3680 | H23: 1770
A24: Capacity Cell.Rack Positions | B24: Rack Positions | C24: 48 | D24: 144 | E24: 144 | F24: 144 | G24: 144 | H24: 24
A25: Capacity Cell.Rack Count | B25: Rack Count | C25: 36 | D25: =D12 -> 52 | E25: =E12 -> 52 | F25: =F12 -> 52 | G25: =G12 -> 52 | H25: 24
A26: Capacity Cell.Allocated ITLoad | B26: Allocated ITLoad | C26: 450 | D26: =D4 -> 1560 | E26: =E4 -> 1560 | F26: =F4 -> 1560 | G26: =G4 -> 1560 | H26: 1395
A27: Capacity Cell.Power Load | B27: Power Load | C27: =C4 -> 450 | D27: =D4 -> 1560 | E27: =E4 -> 1560 | F27: =F4 -> 1560 | G27: =G4 -> 1560 | H27: =H4 -> 1395
A28: Capacity Cell.Power Capacity | B28: Power Capacity | C28: 920 | D28: 3680 | E28: 3680 | F28: 3680 | G28: 3680 | H28: 1840
A29: Capacity Cell.Thermal Load | B29: Thermal Load | C29: =C4 -> 450 | D29: =D4 -> 1560 | E29: =E4 -> 1560 | F29: =F4 -> 1560 | G29: =G4 -> 1560 | H29: =H4 -> 1395
A30: Capacity Cell.Cooling Capacity | B30: Cooling Capacity | C30: 940 | D30: 3840 | E30: 3840 | F30: 3840 | G30: 3840 | H30: 1770
A32: Capacity Cell.Power Infrastructure nodes | B32: Power | C32: RPP-R1-1, RPP-R1-2, RPP-R2-1, RPP-R2-2 | D32: RPP-R3-A1, RPP-R3-A2, RPP-R3-A3, RPP-R3-A4, RPP-R3-B1, RPP-R3-B2, RPP-R3-B3, RPP-R3-B4 | E32: =D32 -> RPP-R3-A1, RPP-R3-A2, RPP-R3-A3, RPP-R3-A4, RPP-R3-B1, RPP-R3-B2, RPP-R3-B3, RPP-R3-B4 | F32: =E32 -> RPP-R3-A1, RPP-R3-A2, RPP-R3-A3, RPP-R3-A4, RPP-R3-B1, RPP-R3-B2, RPP-R3-B3, RPP-R3-B4 | G32: =F32 -> RPP-R3-A1, RPP-R3-A2, RPP-R3-A3, RPP-R3-A4, RPP-R3-B1, RPP-R3-B2, RPP-R3-B3, RPP-R3-B4 | H32: RPP-R5-A3, RPP-R5-A4, RPP-R5-B3, RPP-R5-B4
A33: Capacity Cell.Cooling Infrastructure nodes | B33: Cooling | C33: AIRZONE-R1, AIRZONE-R2, LL-R1, LL-R2 | D33: AIRZONE-R3-E1, AIRZONE-R3-E2, AIRZONE-R3-W1, AIRZONE-R3-W2, LL-R3-E, LL-R3-W | E33: =D33 -> AIRZONE-R3-E1, AIRZONE-R3-E2, AIRZONE-R3-W1, AIRZONE-R3-W2, LL-R3-E, LL-R3-W | F33: =E33 -> AIRZONE-R3-E1, AIRZONE-R3-E2, AIRZONE-R3-W1, AIRZONE-R3-W2, LL-R3-E, LL-R3-W | G33: =F33 -> AIRZONE-R3-E1, AIRZONE-R3-E2, AIRZONE-R3-W1, AIRZONE-R3-W2, LL-R3-E, LL-R3-W | H33: AIRZONE-R5-E, LL-R5-E
G44: Chagne this to Power Redundancy
G49: "Placement"
G59: Change this to two numbers: Thermal Load/ Cooling Capacity (kW)
F69: Change this to two numbers: Power Load/ Power Capacity
E72: Change from "Thermal" to "Cooling"

Sheet Topology
A1: Node Type | B1: Selected Topology | C1: Direction | D1: Edge Level | E1: Parent Node Type | F1: Child Node Type | G1: Collapse
A2: Rack | B2: Spatial Topology | C2: Upstream (left) | D2: 1 | E2: Row | F2: Rack
A3: Rack | B3: Spatial Topology | C3: Upstream (left) | D3: 2 | E3: Zone | F3: Row
A4: Rack | B4: Spatial Topology | C4: Upstream (left) | D4: 3 | E4: Room | F4: Zone
A5: Rack | B5: Electrical System | C5: Downstream (right) | D5: 1 | E5: Rack | F5: Rack PDU
A6: Rack | B6: Electrical System | C6: Upstream (left) | D6: 1 | E6: RPP | F6: Rack
A7: Rack | B7: Electrical System | C7: Upstream (left) | D7: 2 | E7: Room PDU | F7: RPP
A8: Rack | B8: Electrical System | C8: Upstream (left) | D8: 3 | E8: UPS | F8: Room PDU
A9: Rack | B9: Cooling System | C9: Downstream (right) | D9: 1 | E9: Rack | F9: RDHx
A10: Rack | B10: Cooling System | C10: Downstream (right) | D10: 1 | E10: Rack | F10: DTC
A11: Rack | B11: Cooling System | C11: Upstream (left) | D11: 1 | E11: Air Zone | F11: Rack
A12: Rack | B12: Cooling System | C12: Upstream (left) | D12: 1 | E12: Liquid Loop | F12: Rack
A13: Rack | B13: Cooling System | C13: Upstream (left) | D13: 2 | E13: Air Cooling Unit | F13: Air Zone
... A90: Capacity Cell | B90: Deplooyment Blueprint | C90: Upstream (left) | D90: 2 | E90: Cluster | F90: Placement Draft
